Workbook

Sheet Inputs
A1: DigMore Folding Mini Shovel - Facility Design Calculations (single source of truth)
A2: Blue = input; black = formula; green = link from another sheet; yellow = key designer assumption to confirm. New sheets: Bottleneck, Evaluation (scored), BusinessCase, Traceability.
B4: Parameter | C4: Value | D4: Unit | E4: Note / source
B5: Annual demand | C5: 400000 | D5: shovels/yr | E5: 2026 brief
B6: Workdays per year | C6: 220 | D6: days | E6: 2026 brief
B7: Daily demand (good) | C7: =ROUNDUP(C5/C6,0) -> 1819 | D7: shovels/day | E7: rounded up
B8: Shift length | C8: 540 | D8: min | E8: 9 h (brief)
B9: Breaks | C9: 60 | D9: min | E9: 30+15+15 (brief)
B10: Effective time | C10: =C8-C9 -> 480 | D10: min/day | E10: shift - breaks
B11: Availability (1.0 = brief basis) | C11: 1 | D11: fraction | E11: sized on 480 effective min; lower for a setup/breakdown sensitivity
B12: Available time / machine | C12: =C10*C11 -> 480 | D12: min/day | E12: effective time x availability
B13: Takt time | C13: =ROUND((C10*60)/C7,2) -> 15.83 | D13: s/shovel | E13: effective/daily demand
B14: Scrap rate (cut & stamp) | C14: 0.05 | D14: fraction | E14: brief (those two steps)
B15: Yield | C15: =1-C14 -> 0.95 | D15: fraction | E15: 1 - scrap
B16: Pipes per cut | C16: 1 | D16: pipes | E16: bundle cutting raises this
B17: Operators per machine | C17: 1 | D17: - | E17: baseline 1:1
B18: Packaging cycle (assumed) | C18: 30 | D18: s/shovel | E18: brief: workstation-dependent
B19: Tube stock length | C19: 6.5 | D19: m | E19: to verify with supplier
B20: Handle section length | C20: 0.15 | D20: m | E20: brief (150 mm)
B21: Sections per tube | C21: =FLOOR(C19/C20,1) -> 43 | D21: sections | E21: kerf ignored
B22: Tube sections per shovel | C22: 2 | D22: sections | E22: back + middle
B23: Sheet length | C23: 2.5 | D23: m | E23: standard sheet (assumption)
B24: Sheet width | C24: 1.25 | D24: m | E24: standard sheet (assumption)
B25: Nesting efficiency | C25: 0.8 | D25: fraction | E25: assumption
B26: Head blank length | C26: 0.17 | D26: m | E26: finished 150 + allowance (assumption)
B27: Head blank width | C27: 0.14 | D27: m | E27: finished 120 + allowance (assumption)
B28: Hinge blank length | C28: 0.08 | D28: m | E28: assumption
B29: Hinge blank width | C29: 0.05 | D29: m | E29: assumption
B30: Raw material cover | C30: 10 | D30: days | E30: 2 weeks (brief)
B31: Finished goods cover | C31: 20 | D31: days | E31: 4 weeks (brief)
B32: WIP buffer | C32: 1 | D32: days | E32: about one shift (assumption)
B33: Units per box | C33: 8 | D33: shovels | E33: assumption
B34: Boxes per pallet | C34: 45 | D34: boxes | E34: assumption
B35: Units per pallet | C35: =C33*C34 -> 360 | D35: shovels | E35: box x pallet
B36: Pallet length | C36: 1.2 | D36: m | E36: standard (assumption)
B37: Pallet width | C37: 1 | D37: m | E37: standard (assumption)
B38: Pallet footprint | C38: =C36*C37 -> 1.2 | D38: m2
B39: Storage levels (racking) | C39: 4 | D39: - | E39: assumption
B40: Tubes per cantilever rack | C40: 200 | D40: tubes | E40: assumption
B41: Cantilever rack footprint | C41: 5 | D41: m2 | E41: 6 m x 1 m (assumption)
...

Sheet Demand
A1: Demand and production requirement
A3: Measure | B3: Value | C3: Unit | D3: Basis
A4: Annual demand | B4: =Inputs!$C$5 -> 400000 | C4: shovels/yr | D4: brief
A5: Workdays | B5: =Inputs!$C$6 -> 220 | C5: days | D5: brief
A6: Daily demand (good) | B6: =Inputs!$C$7 -> 1819 | C6: shovels/day | D6: annual/days, round up
A7: Effective time | B7: =Inputs!$C$10 -> 480 | C7: min/day | D7: shift - breaks
A8: Hourly demand | B8: =Inputs!$C$7/(Inputs!$C$10/60) -> 227.375 | C8: shovels/h | D8: daily/effective hours
A9: Takt time | B9: =Inputs!$C$13 -> 15.83 | C9: s/shovel | D9: effective/daily
A11: Part-level daily requirement
A12: Part | B12: Per shovel | C12: Good/day | D12: Gross/day (if scrap step)
A13: Back handle section (tube) | B13: 1 | C13: =B13*Inputs!$C$7 -> 1819
A14: Middle handle section (tube) | B14: 1 | C14: =B14*Inputs!$C$7 -> 1819
A15: Handle sections cut (tube) | B15: 2 | C15: =B15*Inputs!$C$7 -> 3638 | D15: =C15/Inputs!$C$15 -> 3829.4737
A16: Shovel head (sheet) | B16: 1 | C16: =B16*Inputs!$C$7 -> 1819 | D16: =C16/Inputs!$C$15 -> 1914.7368
A17: Hinge connector (sheet) | B17: 1 | C17: =B17*Inputs!$C$7 -> 1819 | D17: =C17/Inputs!$C$15 -> 1914.7368

Sheet Capacity
A1: Per-process capacity: machines and operators
A3: Process | B3: Basis | C3: Units/shovel | D3: Scrap? | E3: Daily good | F3: Scrap factor | G3: Daily gross | H3: Pieces/op | I3: Ops/day | J3: Cycle (s) | K3: Time (min/day) | L3: Prod min/mach | M3: Machines | N3: Util. | O3: Operators | P3: Note
A4: Cut handle | B4: per cut | C4: 2 | D4: Yes | E4: =Inputs!$C$7*C4 -> 3638 | F4: =IF(D4="Yes",1/Inputs!$C$15,1) -> 1.0526316 | G4: =E4*F4 -> 3829.4737 | H4: =Inputs!$C$16 -> 1 | I4: =G4/H4 -> 3829.4737 | J4: 15 | K4: =I4*J4/60 -> 957.36842 | L4: =Inputs!$C$12 -> 480 | M4: =ROUNDUP(K4/L4,0) -> 2 | N4: =K4/(M4*L4) -> 0.99725877 | O4: =M4*Inputs!$C$17 -> 2 | P4: 5% scrap; pipes/cut from equipment
A5: Internal thread (middle) | B5: per pipe | C5: 1 | D5: No | E5: =$G$4/$C$4 -> 1914.7368 | F5: =IF(D5="Yes",1/Inputs!$C$15,1) -> 1 | G5: =E5*F5 -> 1914.7368 | H5: 1 | I5: =G5/H5 -> 1914.7368 | J5: 20 | K5: =I5*J5/60 -> 638.24561 | L5: =Inputs!$C$12 -> 480 | M5: =ROUNDUP(K5/L5,0) -> 2 | N5: =K5/(M5*L5) -> 0.66483918 | O5: =M5*Inputs!$C$17 -> 2 | P5: brief; input = gross tubes surviving cut (cumulative scrap, Tompkins Eq.2.3)
A6: Stamp / narrow end (grip) | B6: per pipe | C6: 1 | D6: No | E6: =$G$4/$C$4 -> 1914.7368 | F6: =IF(D6="Yes",1/Inputs!$C$15,1) -> 1 | G6: =E6*F6 -> 1914.7368 | H6: 1 | I6: =G6/H6 -> 1914.7368 | J6: 5 | K6: =I6*J6/60 -> 159.5614 | L6: =Inputs!$C$12 -> 480 | M6: =ROUNDUP(K6/L6,0) -> 1 | N6: =K6/(M6*L6) -> 0.33241959 | O6: =M6*Inputs!$C$17 -> 1 | P6: brief; input = gross tubes surviving cut (cumulative scrap, Tompkins Eq.2.3)
A7: Knurl + external thread (grip) | B7: per pipe | C7: 1 | D7: No | E7: =$G$4/$C$4 -> 1914.7368 | F7: =IF(D7="Yes",1/Inputs!$C$15,1) -> 1 | G7: =E7*F7 -> 1914.7368 | H7: 1 | I7: =G7/H7 -> 1914.7368 | J7: 60 | K7: =I7*J7/60 -> 1914.7368 | L7: =Inputs!$C$12 -> 480 | M7: =ROUNDUP(K7/L7,0) -> 4 | N7: =K7/(M7*L7) -> 0.99725877 | O7: =M7*Inputs!$C$17 -> 4 | P7: thread rolling can cut this; input = gross tubes surviving cut (cumulative scrap)
A8: Stamp shovel head | B8: per part | C8: 1 | D8: Yes | E8: =Inputs!$C$7*C8 -> 1819 | F8: =IF(D8="Yes",1/Inputs!$C$15,1) -> 1.0526316 | G8: =E8*F8 -> 1914.7368 | H8: 1 | I8: =G8/H8 -> 1914.7368 | J8: 2 | K8: =I8*J8/60 -> 63.824561 | L8: =Inputs!$C$12 -> 480 | M8: =ROUNDUP(K8/L8,0) -> 1 | N8: =K8/(M8*L8) -> 0.13296784 | O8: =M8*Inputs!$C$17 -> 1 | P8: 5% scrap
A9: Shape / bend head | B9: per head | C9: 1 | D9: No | E9: =Inputs!$C$7*C9 -> 1819 | F9: =IF(D9="Yes",1/Inputs!$C$15,1) -> 1 | G9: =E9*F9 -> 1819 | H9: 1 | I9: =G9/H9 -> 1819 | J9: 2 | K9: =I9*J9/60 -> 60.633333 | L9: =Inputs!$C$12 -> 480 | M9: =ROUNDUP(K9/L9,0) -> 1 | N9: =K9/(M9*L9) -> 0.12631944 | O9: =M9*Inputs!$C$17 -> 1 | P9: brief
A10: Sharpen blade | B10: per shovel | C10: 1 | D10: No | E10: =Inputs!$C$7*C10 -> 1819 | F10: =IF(D10="Yes",1/Inputs!$C$15,1) -> 1 | G10: =E10*F10 -> 1819 | H10: 1 | I10: =G10/H10 -> 1819 | J10: 120 | K10: =I10*J10/60 -> 3638 | L10: =Inputs!$C$12 -> 480 | M10: =ROUNDUP(K10/L10,0) -> 8 | N10: =K10/(M10*L10) -> 0.94739583 | O10: =M10*Inputs!$C$17 -> 8 | P10: main bottleneck
A11: Serrate edge | B11: per shovel | C11: 1 | D11: No | E11: =Inputs!$C$7*C11 -> 1819 | F11: =IF(D11="Yes",1/Inputs!$C$15,1) -> 1 | G11: =E11*F11 -> 1819 | H11: 1 | I11: =G11/H11 -> 1819 | J11: 60 | K11: =I11*J11/60 -> 1819 | L11: =Inputs!$C$12 -> 480 | M11: =ROUNDUP(K11/L11,0) -> 4 | N11: =K11/(M11*L11) -> 0.94739583 | O11: =M11*Inputs!$C$17 -> 4 | P11: brief
A12: Stamp hinge connector | B12: per part | C12: 1 | D12: Yes | E12: =Inputs!$C$7*C12 -> 1819 | F12: =IF(D12="Yes",1/Inputs!$C$15,1) -> 1.0526316 | G12: =E12*F12 -> 1914.7368 | H12: 1 | I12: =G12/H12 -> 1914.7368 | J12: 2 | K12: =I12*J12/60 -> 63.824561 | L12: =Inputs!$C$12 -> 480 | M12: =ROUNDUP(K12/L12,0) -> 1 | N12: =K12/(M12*L12) -> 0.13296784 | O12: =M12*Inputs!$C$17 -> 1 | P12: 5% scrap
A13: Bend hinge connector | B13: per part | C13: 1 | D13: No | E13: =Inputs!$C$7*C13 -> 1819 | F13: =IF(D13="Yes",1/Inputs!$C$15,1) -> 1 | G13: =E13*F13 -> 1819 | H13: 1 | I13: =G13/H13 -> 1819 | J13: 5 | K13: =I13*J13/60 -> 151.58333 | L13: =Inputs!$C$12 -> 480 | M13: =ROUNDUP(K13/L13,0) -> 1 | N13: =K13/(M13*L13) -> 0.31579861 | O13: =M13*Inputs!$C$17 -> 1 | P13: brief
A14: Rivet hinge to head | B14: per shovel | C14: 1 | D14: No | E14: =Inputs!$C$7*C14 -> 1819 | F14: =IF(D14="Yes",1/Inputs!$C$15,1) -> 1 | G14: =E14*F14 -> 1819 | H14: 1 | I14: =G14/H14 -> 1819 | J14: 5 | K14: =I14*J14/60 -> 151.58333 | L14: =Inputs!$C$12 -> 480 | M14: =ROUNDUP(K14/L14,0) -> 1 | N14: =K14/(M14*L14) -> 0.31579861 | O14: =M14*Inputs!$C$17 -> 1 | P14: brief
A15: Hand polish / deburr | B15: per head | C15: 1 | D15: No | E15: =Inputs!$C$7*C15 -> 1819 | F15: =IF(D15="Yes",1/Inputs!$C$15,1) -> 1 | G15: =E15*F15 -> 1819 | H15: 1 | I15: =G15/H15 -> 1819 | J15: 60 | K15: =I15*J15/60 -> 1819 | L15: =Inputs!$C$12 -> 480 | M15: =ROUNDUP(K15/L15,0) -> 4 | N15: =K15/(M15*L15) -> 0.94739583 | O15: =M15*Inputs!$C$17 -> 4 | P15: brief
A16: Final assembly | B16: per shovel | C16: 1 | D16: No | E16: =Inputs!$C$7*C16 -> 1819 | F16: =IF(D16="Yes",1/Inputs!$C$15,1) -> 1 | G16: =E16*F16 -> 1819 | H16: 1 | I16: =G16/H16 -> 1819 | J16: 30 | K16: =I16*J16/60 -> 909.5 | L16: =Inputs!$C$12 -> 480 | M16: =ROUNDUP(K16/L16,0) -> 2 | N16: =K16/(M16*L16) -> 0.94739583 | O16: =M16*Inputs!$C$17 -> 2 | P16: brief
A17: Packaging (hand + check) | B17: per shovel | C17: 1 | D17: No | E17: =Inputs!$C$7*C17 -> 1819 | F17: =IF(D17="Yes",1/Inputs!$C$15,1) -> 1 | G17: =E17*F17 -> 1819 | H17: 1 | I17: =G17/H17 -> 1819 | J17: =Inputs!$C$18 -> 30 | K17: =I17*J17/60 -> 909.5 | L17: =Inputs!$C$12 -> 480 | M17: =ROUNDUP(K17/L17,0) -> 2 | N17: =K17/(M17*L17) -> 0.94739583 | O17: =M17*Inputs!$C$17 -> 2 | P17: cycle is an assumption
A18: TOTAL (line processes) | M18: =SUM(M4:M17) -> 34 | O18: =SUM(O4:O17) -> 34
A19: Average utilisation | N19: =AVERAGE(N4:N17) -> 0.62518627

Sheet Equipment-dep
A1: Equipment-dependent processes (no brief cycle time)
A3: Powder coating (conveyorised, enclosed)
A5: Coated items per day | B5: =Inputs!$C$7*Inputs!$C$46 -> 5457 | C5: items/day
A6: Assumed line rate | B6: =Inputs!$C$45 -> 600 | C6: parts/h
A7: Hours needed | B7: =B5/B6 -> 9.095 | C7: h/day
A8: Productive hours/shift | B8: =Inputs!$C$12/60 -> 8 | C8: h
A9: Powder lines required | B9: =ROUNDUP(B7/B8,0) -> 2 | C9: lines
A10: At 600 parts/h the line exceeds one shift; about 680 parts/h or a second line is needed.
A12: Heat treatment (T6 ageing, batch oven)
A13: Subassemblies per day | B13: =Inputs!$C$7 -> 1819 | C13: items/day
A14: Assumed cycle | B14: =Inputs!$C$44 -> 6 | C14: h/batch
A15: Ageing ovens (assumed) | B15: 1 | C15: ovens
A16: Oven sized to ~1 day of subassemblies; runs across/after the shift. Supplier-based; verify.
A18: Sandblasting (enclosed booth)
A19: Heads per day | B19: =Inputs!$C$7 -> 1819 | C19: items/day
A20: Throughput and booth count: supplier-based estimate required.

Sheet RawMaterials
A1: Raw material requirements
A3: Aluminium round tube
A4: Sections per shovel | B4: =Inputs!$C$22 -> 2 | C4: sections
A5: Good sections/day | B5: =Inputs!$C$7*B4 -> 3638 | C5: sections/day
A6: Gross sections/day (scrap) | B6: =B5/Inputs!$C$15 -> 3829.4737 | C6: sections/day
A7: Sections per 6 m tube | B7: =Inputs!$C$21 -> 43 | C7: sections
A8: Tubes per day | B8: =ROUNDUP(B6/B7,0) -> 90 | C8: tubes/day
A9: Tubes for 2 weeks | B9: =B8*Inputs!$C$30 -> 900 | C9: tubes
A11: Aluminium sheet
A12: Sheet area | B12: =Inputs!$C$23*Inputs!$C$24 -> 3.125 | C12: m2
A13: Head blank area | B13: =Inputs!$C$26*Inputs!$C$27 -> 0.0238 | C13: m2
A14: Hinge blank area | B14: =Inputs!$C$28*Inputs!$C$29 -> 0.004 | C14: m2
A15: Heads per sheet (nested) | B15: =FLOOR(B12*Inputs!$C$25/B13,1) -> 105 | C15: parts
A16: Hinges per sheet (nested) | B16: =FLOOR(B12*Inputs!$C$25/B14,1) -> 625 | C16: parts
A17: Gross heads/day | B17: =Inputs!$C$7/Inputs!$C$15 -> 1914.7368 | C17: parts/day
A18: Gross hinges/day | B18: =Inputs!$C$7/Inputs!$C$15 -> 1914.7368 | C18: parts/day
A19: Sheets/day (heads) | B19: =ROUNDUP(B17/B15,0) -> 19 | C19: sheets/day
A20: Sheets/day (hinges) | B20: =ROUNDUP(B18/B16,0) -> 4 | C20: sheets/day
A21: Total sheets/day | B21: =B19+B20 -> 23 | C21: sheets/day
A22: Sheets for 2 weeks | B22: =B21*Inputs!$C$30 -> 230 | C22: sheets

Sheet Inventory_Pack
A1: Inventory levels and packaging unit loads
A3: Inventory (shovel-equivalents)
A4: Raw material on hand (2 wk) | B4: =Inputs!$C$30*Inputs!$C$7 -> 18190 | C4: shovels
A5: Finished goods (4 wk) | B5: =Inputs!$C$31*Inputs!$C$7 -> 36380 | C5: shovels
A6: WIP buffer (~1 shift) | B6: =Inputs!$C$32*Inputs!$C$7 -> 1819 | C6: shovels
A8: Packaging and order definitions
A9: Units per box | B9: =Inputs!$C$33 -> 8 | C9: shovels
A10: Boxes per pallet | B10: =Inputs!$C$34 -> 45 | C10: boxes
A11: Units per pallet | B11: =Inputs!$C$35 -> 360 | C11: shovels
A12: Boxes per day | B12: =ROUNDUP(Inputs!$C$7/Inputs!$C$33,0) -> 228 | C12: boxes/day
A13: Pallets per day | B13: =ROUNDUP(Inputs!$C$7/Inputs!$C$35,0) -> 6 | C13: pallets/day
A14: Small order (<= 1 pallet) | B14: =Inputs!$C$35 -> 360 | C14: shovels max
A15: Large order (> 1 pallet) | B15: >400 | C15: shovels

Sheet Storage_3D
A1: Storage sizing (3D footprint)
A3: Store | B3: Items | C3: Racks/positions | D3: Floor area (m2) | E3: Basis
A4: Raw tube | B4: =RawMaterials!B9 -> 900 | C4: =ROUNDUP(RawMaterials!B9/Inputs!$C$40,0) -> 5 | D4: =C4*Inputs!$C$41*Inputs!$C$43 -> 37.5 | E4: cantilever racks
A5: Raw sheet | B5: =RawMaterials!B22 -> 230 | C5: =ROUNDUP(RawMaterials!B22/Inputs!$C$42,0) -> 2 | D5: =C5*(Inputs!$C$23*Inputs!$C$24)*Inputs!$C$43 -> 9.375 | E5: sheet stacks
A6: Finished goods | B6: =ROUNDUP(Inventory_Pack!B5/Inputs!$C$35,0) -> 102 | C6: =ROUNDUP(B6/Inputs!$C$39,0) -> 26 | D6: =C6*Inputs!$C$38*Inputs!$C$43 -> 46.8 | E6: palletised, racked
A7: WIP staging | B7: =ROUNDUP(Inventory_Pack!B6/Inputs!$C$35,0) -> 6 | C7: =ROUNDUP(B7/Inputs!$C$39,0) -> 2 | D7: =C7*Inputs!$C$38*Inputs!$C$43 -> 3.6 | E7: decoupling buffers
A8: Scrap / waste | B8: - | C8: - | D8: =Inputs!$C$52 -> 30 | E8: assumption
A9: Total storage area | D9: =SUM(D4:D8) -> 127.275

Sheet Personnel
A1: Personnel (headcount)
A3: Category / role | B3: Number | C3: Note
A4: Senior Plant Manager | B4: 1 | C4: brief
A5: Operations Manager | B5: 1 | C5: brief
A6: Inventory Manager | B6: 1 | C6: brief
A7: Reception | B7: 1 | C7: brief
A8: Purchasing | B8: 1 | C8: brief
A9: Sales | B9: 2 | C9: brief (assumed count)
A10: Finance | B10: 1 | C10: brief
A11: Marketing | B11: 1 | C11: brief
A12: Human Resources | B12: 1 | C12: brief
A13: Plant supervisors | B13: 3 | C13: ~1 per dept (assumption)
A14: Security | B14: 2 | C14: assumption
A15: Material handlers / forklift | B15: 4 | C15: assumption
A16: Equipment-dep & QA operators | B16: 5 | C16: heat/sandblast/powder/inspection (assumption)
A17: Production operators (from Capacity) | B17: =Capacity!O18 -> 34 | C17: line processes, 1:1
A18: TOTAL headcount | B18: =SUM(B4:B17) -> 58

Sheet Parking
A1: Parking and site vehicle provision
A3: Total on-site headcount | B3: =Personnel!B18 -> 58 | C3: people
A4: Employee bays | B4: =B3*Inputs!$C$56 -> 58 | C4: bays
A5: Visitor + collection bays | B5: =Inputs!$C$57 -> 8 | C5: bays
A6: Total car bays | B6: =B4+B5 -> 66 | C6: bays
A7: Car parking area | B7: =B6*Inputs!$C$58 -> 1848 | C7: m2
A8: Truck fleet bays | B8: =Inputs!$C$59 -> 5 | C8: bays
A9: Truck fleet area | B9: =B8*Inputs!$C$60 -> 350 | C9: m2
A10: Total vehicle area | B10: =B7+B9 -> 2198 | C10: m2

Sheet Space_Summary
A1: Space summary and total footprint
A3: Area / department | B3: Floor area (m2) | C3: Basis
A4: Production workstations | B4: =Capacity!M18*Inputs!$C$47 -> 238 | C4: machines x area/workstation
A5: Powder coating (enclosed) | B5: =Inputs!$C$50 -> 135 | C5: supplier-based estimate
A6: Heat treat + sandblast | B6: =Inputs!$C$51 -> 70 | C6: supplier-based estimate
A7: Raw material + WIP + scrap storage | B7: =Storage_3D!D4+Storage_3D!D5+Storage_3D!D7+Storage_3D!D8 -> 80.475 | C7: from Storage_3D
A8: Finished goods storage | B8: =Storage_3D!D6 -> 46.8 | C8: from Storage_3D
A9: Receiving + dispatch | B9: =Inputs!$C$53 -> 220 | C9: docks + staging (assumption)
A10: Offices | B10: =(Personnel!B18-Capacity!O18)*Inputs!$C$54 -> 216 | C10: non-operator staff x area/person
A11: Amenities (lockers/restrooms/cafeteria) | B11: =Personnel!B18*Inputs!$C$55 -> 203 | C11: headcount x area/person
A12: Subtotal (functional floor) | B12: =SUM(B4:B11) -> 1209.275
A13: Circulation / aisles | B13: =B12*Inputs!$C$48 -> 302.31875 | C13: allowance
A14: Building subtotal | B14: =B12+B13 -> 1511.5938
A15: Future expansion (~10%) | B15: =ROUND(B14*Inputs!$C$49,0) -> 151
A16: TOTAL BUILDING | B16: =ROUND(B14+B15,0) -> 1663
A18: Parking + truck fleet (site) | B18: =Parking!B10 -> 2198 | C18: from Parking
A19: INDICATIVE SITE FOOTPRINT | B19: =ROUND(B16+B18,0) -> 3861

Sheet Machinery
A1: Recommended machinery (types and sources; dimensions/cost supplier-based)
A3: Process / area | B3: Recommended type | C3: Throughput / source note | D3: Dimensions | E3: Cost | F3: Status
A4: Cut handle | B4: Automatic non-ferrous cold saw, auto bar-feed, bundle cutting | C4: bundle cutting available (Addison Saws; Profifeed A550) | D4: supplier | E4: quote | F4: verify
A5: Threads + knurl | B5: Thread-rolling machine + knurling head | C5: 15-60+ parts/min (PowerTransmission; IQS) | D5: supplier | E5: quote | F5: verify
A6: Stamping (head/hinge/narrow) | B6: Mechanical power press + progressive die | C6: standard | D6: supplier | E6: quote | F6: verify
A7: Bending | B7: Press brake | C7: standard | D7: supplier | E7: quote | F7: verify
A8: Sharpen / serrate | B8: Automated grinding / serrating machine | C8: replaces 2 min / 1 min manual | D8: supplier | E8: quote | F8: verify
A9: Rivet | B9: Pneumatic / hydraulic riveter | C9: standard | D9: supplier | E9: quote | F9: verify
A10: Heat treat | B10: T6 artificial-ageing batch oven | C10: 5-8 h cycle (ARC; Aluminium-guide) | D10: supplier | E10: quote | F10: verify
A11: Sandblast | B11: Enclosed blast booth + extraction | C11: equipment-dependent | D11: supplier | E11: quote | F11: verify
A12: Powder coat | B12: Conveyorised powder line (booth + oven) | C12: ~600 parts/h; cure ~10-20 min (TheFabricator) | D12: supplier | E12: quote | F12: verify
A13: Assembly / packaging | B13: Manual workstations | C13: by hand + visual check (brief) | D13: - | E13: - | F13: stations from Capacity
A15: No machine dimensions or costs are invented; obtain from supplier quotations.

Sheet Evaluation
A1: Alternatives evaluation matrix (template - scores to be filled for 3 layouts)
A3: Criterion (from brief) | B3: Weight | C3: Alt 1: Linear spine | D3: Alt 2: U-shape return | E3: Alt 3: Parallel-branch + finishing spine | F3: Alt1 wtd | G3: Alt2 wtd | H3: Alt3 wtd
A4: Meets demand of 400 000/yr | B4: 0.2 | C4: 5 | D4: 5 | E4: 5 | F4: =B4*C4 -> 1 | G4: =B4*D4 -> 1 | H4: =B4*E4 -> 1
A5: Logical material flow (receiving to dispatch) | B5: 0.2 | C5: 5 | D5: 3 | E5: 4 | F5: =B5*C5 -> 1 | G5: =B5*D5 -> 0.6 | H5: =B5*E5 -> 0.8
A6: Enclosed powder coating + hazard separation | B6: 0.15 | C6: 3 | D6: 2 | E6: 5 | F6: =B6*C6 -> 0.45 | G6: =B6*D6 -> 0.3 | H6: =B6*E6 -> 0.75
A7: Efficient storage and material handling | B7: 0.15 | C7: 3 | D7: 4 | E7: 3 | F7: =B7*C7 -> 0.45 | G7: =B7*D7 -> 0.6 | H7: =B7*E7 -> 0.45
A8: Pedestrian / vehicle safety and site access | B8: 0.1 | C8: 4 | D8: 3 | E8: 4 | F8: =B8*C8 -> 0.4 | G8: =B8*D8 -> 0.3 | H8: =B8*E8 -> 0.4
A9: ~10% expansion provision | B9: 0.1 | C9: 3 | D9: 2 | E9: 5 | F9: =B9*C9 -> 0.3 | G9: =B9*D9 -> 0.2 | H9: =B9*E9 -> 0.5
A10: Ease of construction / implementation | B10: 0.1 | C10: 5 | D10: 4 | E10: 3 | F10: =B10*C10 -> 0.5 | G10: =B10*D10 -> 0.4 | H10: =B10*E10 -> 0.3
A11: TOTAL | B11: =SUM(B4:B10) -> 1 | F11: =SUM(F4:F10) -> 4.1 | G11: =SUM(G4:G10) -> 3.4 | H11: =SUM(H4:H10) -> 4.2
A13: Scoring rubric: 1 poor, 2 weak, 3 acceptable, 4 good, 5 excellent (anchored to each criterion).
A14: Alt 1 (Linear spine): one-direction flow from receiving to dispatch; cells laid out left-to-right. Strong logical flow and easy construction; powder-coat mid-line forces longer fume duct runs and intersects pedestrian routes.
A15: Alt 2 (U-shape): receiving and dispatch share one face; flow wraps around. Best compactness and material handling, but powder-coat enclosure crowded against active work and weak expansion margin in tight footprint.
A16: Alt 3 (Parallel-branch + finishing spine): tube and sheet feeders run as two parallel halls feeding a perpendicular finishing+assembly+pack spine; powder-coat as a separated block off the spine with dedicated extraction. Strongest hazard separation and 10% expansion margin (add another feeder cell); slightly higher build complexity and pedestrian crossings.
A17: Recommended: highest weighted score = chosen alternative; ties broken in favour of rigorous hazard isolation and expansion margin (Alt 3) given the brief's enclosed-powder-coat and 10%-growth requirements.

Sheet Report Map - Ch6
A1: Chapter 6 - Detail Design Specifications : Report Map (live figures track the workbook)
A2: Insert AFTER Requirements/Assumptions chapter and BEFORE Design Alternatives. Each table needs a caption + an in-text reference (brief requirement).
A4: Report section (create in 417.docx) | B4: Source sheet / range | C4: Table caption to use | D4: Governing equation | E4: Key live figure | F4: Value (live) | G4: Benchmark precedent
A5: 6.1 Demand & Production Requirement | B5: Demand!A3:D9 | C5: Table 4: Demand and production requirement | D5: Daily = ROUNDUP(Annual / Workdays); Takt = Effective time / Daily demand | E5: Takt time (s/shovel) | F5: =Demand!B9 -> 15.83 | G5: B Table 2; A Tables 7-8
A6: 6.1 Demand & Production Requirement | B6: Demand!A11:D17 | C6: Table 5: Part-level daily requirement | D6: Gross = Good / (1 - scrap) [Tompkins Eq.2.2] | E6: Daily demand (shovels/day) | F6: =Demand!B6 -> 1819 | G6: B Table 2; A Table 7
A7: 6.2 Raw Material Requirements | B7: RawMaterials!A3:C9 | C7: Table 6: Aluminium tube requirement | D7: Tubes/day = Gross sections per day / Sections per 6 m tube | E7: Tubes per day | F7: =RawMaterials!B8 -> 90 | G7: B Table 3; A Tables 6, 18
A8: 6.2 Raw Material Requirements | B8: RawMaterials!A11:C22 | C8: Table 7: Aluminium sheet requirement | D8: Sheets/day = Gross parts per day / Parts nested per sheet | E8: Total sheets per day | F8: =RawMaterials!B21 -> 23 | G8: B Table 3; A Tables 6, 18
A9: 6.3 Manufacturing Time & Takt | B9: Inputs!B8:E13 | C9: Table 8: Shift, effective time and takt | D9: Effective time = Shift - Breaks; Takt = Effective / Daily demand | E9: Effective time (min/day) | F9: =Inputs!C10 -> 480 | G9: B Section 6.2; A Table 1
A10: 6.4 Capacity Analysis (machines & operators) | B10: Capacity!A3:P19 | C10: Table 9: Per-process capacity analysis | D10: Machines = ROUNDUP((Daily gross x Cycle) / Effective time) [Tompkins Eq.2.5] | E10: Total machines (line) | F10: =Capacity!M18 -> 34 | G10: B Table 9; A Tables 9-16 (CORE EXHIBIT)
A11: 6.4 Capacity Analysis (machines & operators) | B11: Capacity!O18 | C11: Table 9 (cont.): Operator requirement | D11: Operators = Machines x Operators per machine (1:1 baseline) | E11: Total operators (line) | F11: =Capacity!O18 -> 34 | G11: B Table 9; A Tables 9-16
A12: 6.4 Capacity Analysis - bottleneck note | B12: Capacity!A10 / N19 | C12: In-text: bottleneck & average utilisation | D12: Util = Time(min/day) / (Machines x Effective time) | E12: Average utilisation | F12: =Capacity!N19 -> 0.62518627 | G12: B Section 6 narrative
A13: 6.5 Equipment-dependent processes | B13: Equipment-dep!A3:C20 | C13: Table 10: Equipment-dependent processes | D13: Lines = ROUNDUP(Items/day / (Line rate x Productive hours)) | E13: Powder lines required | F13: ='Equipment-dep'!B9 -> 2 | G13: B Tables 17-19
A15: RULE: Everything spreadsheet-derived (6.1-6.5, and later the Ch7 space tables) must precede the Design Alternatives / MFP chapters, because layout decisions depend on these numbers.

Sheet Bottleneck
A1: Bottleneck analysis and demand sensitivity
A2: Pulls live from Capacity. Highest utilisation = constraint; +10% demand shows expansion margin.
A4: Process | B4: Machines | C4: Utilisation | D4: Status | E4: +10% util | F4: Action if +10%
A5: =Capacity!A4 -> Cut handle | B5: =Capacity!M4 -> 2 | C5: =Capacity!N4 -> 0.99725877 | D5: =IF(C5>=0.9,"CONSTRAINT",IF(C5>=0.7,"near","")) -> CONSTRAINT | E5: =C5*1.1 -> 1.0969846 | F5: =IF(E5>1,"add 1 machine",IF(E5>=0.95,"watch","")) -> add 1 machine
A6: =Capacity!A5 -> Internal thread (middle) | B6: =Capacity!M5 -> 2 | C6: =Capacity!N5 -> 0.66483918 | D6: =IF(C6>=0.9,"CONSTRAINT",IF(C6>=0.7,"near","")) | E6: =C6*1.1 -> 0.7313231 | F6: =IF(E6>1,"add 1 machine",IF(E6>=0.95,"watch",""))
A7: =Capacity!A6 -> Stamp / narrow end (grip) | B7: =Capacity!M6 -> 1 | C7: =Capacity!N6 -> 0.33241959 | D7: =IF(C7>=0.9,"CONSTRAINT",IF(C7>=0.7,"near","")) | E7: =C7*1.1 -> 0.36566155 | F7: =IF(E7>1,"add 1 machine",IF(E7>=0.95,"watch",""))
A8: =Capacity!A7 -> Knurl + external thread (grip) | B8: =Capacity!M7 -> 4 | C8: =Capacity!N7 -> 0.99725877 | D8: =IF(C8>=0.9,"CONSTRAINT",IF(C8>=0.7,"near","")) -> CONSTRAINT | E8: =C8*1.1 -> 1.0969846 | F8: =IF(E8>1,"add 1 machine",IF(E8>=0.95,"watch","")) -> add 1 machine
A9: =Capacity!A8 -> Stamp shovel head | B9: =Capacity!M8 -> 1 | C9: =Capacity!N8 -> 0.13296784 | D9: =IF(C9>=0.9,"CONSTRAINT",IF(C9>=0.7,"near","")) | E9: =C9*1.1 -> 0.14626462 | F9: =IF(E9>1,"add 1 machine",IF(E9>=0.95,"watch",""))
A10: =Capacity!A9 -> Shape / bend head | B10: =Capacity!M9 -> 1 | C10: =Capacity!N9 -> 0.12631944 | D10: =IF(C10>=0.9,"CONSTRAINT",IF(C10>=0.7,"near","")) | E10: =C10*1.1 -> 0.13895139 | F10: =IF(E10>1,"add 1 machine",IF(E10>=0.95,"watch",""))
A11: =Capacity!A10 -> Sharpen blade | B11: =Capacity!M10 -> 8 | C11: =Capacity!N10 -> 0.94739583 | D11: =IF(C11>=0.9,"CONSTRAINT",IF(C11>=0.7,"near","")) -> CONSTRAINT | E11: =C11*1.1 -> 1.0421354 | F11: =IF(E11>1,"add 1 machine",IF(E11>=0.95,"watch","")) -> add 1 machine
A12: =Capacity!A11 -> Serrate edge | B12: =Capacity!M11 -> 4 | C12: =Capacity!N11 -> 0.94739583 | D12: =IF(C12>=0.9,"CONSTRAINT",IF(C12>=0.7,"near","")) -> CONSTRAINT | E12: =C12*1.1 -> 1.0421354 | F12: =IF(E12>1,"add 1 machine",IF(E12>=0.95,"watch","")) -> add 1 machine
A13: =Capacity!A12 -> Stamp hinge connector | B13: =Capacity!M12 -> 1 | C13: =Capacity!N12 -> 0.13296784 | D13: =IF(C13>=0.9,"CONSTRAINT",IF(C13>=0.7,"near","")) | E13: =C13*1.1 -> 0.14626462 | F13: =IF(E13>1,"add 1 machine",IF(E13>=0.95,"watch",""))
A14: =Capacity!A13 -> Bend hinge connector | B14: =Capacity!M13 -> 1 | C14: =Capacity!N13 -> 0.31579861 | D14: =IF(C14>=0.9,"CONSTRAINT",IF(C14>=0.7,"near","")) | E14: =C14*1.1 -> 0.34737847 | F14: =IF(E14>1,"add 1 machine",IF(E14>=0.95,"watch",""))
A15: =Capacity!A14 -> Rivet hinge to head | B15: =Capacity!M14 -> 1 | C15: =Capacity!N14 -> 0.31579861 | D15: =IF(C15>=0.9,"CONSTRAINT",IF(C15>=0.7,"near","")) | E15: =C15*1.1 -> 0.34737847 | F15: =IF(E15>1,"add 1 machine",IF(E15>=0.95,"watch",""))
A16: =Capacity!A15 -> Hand polish / deburr | B16: =Capacity!M15 -> 4 | C16: =Capacity!N15 -> 0.94739583 | D16: =IF(C16>=0.9,"CONSTRAINT",IF(C16>=0.7,"near","")) -> CONSTRAINT | E16: =C16*1.1 -> 1.0421354 | F16: =IF(E16>1,"add 1 machine",IF(E16>=0.95,"watch","")) -> add 1 machine
... A18: =Capacity!A17 -> Packaging (hand + check) | B18: =Capacity!M17 -> 2 | C18: =Capacity!N17 -> 0.94739583 | D18: =IF(C18>=0.9,"CONSTRAINT",IF(C18>=0.7,"near","")) -> CONSTRAINT | E18: =C18*1.1 -> 1.0421354 | F18: =IF(E18>1,"add 1 machine",IF(E18>=0.95,"watch","")) -> add 1 machine
A21: Bottleneck summary (read into report 6.4):
A22: Primary constraints | B22: Sharpen blade; Cut handle; Knurl+thread
A23: Constraint utilisation | B23: at or above 95% on 1-shift basis
A24: Slack stations | B24: Stamping, bending, riveting <35% util
A25: Sensitivity (+10% demand) | B25: Cut handle and Knurl+thread tip over 100% -> add 1 machine each; sharpen at ~104% -> +1 grinder. All other stations absorb without extra capex.
A26: Implication for MFP | B26: Reserve floor area adjacent to cut, knurl+thread and sharpen cells; equals the 10% expansion provision.

Sheet BusinessCase
A1: Chapter 10 Business Case: capex, risks, schedule (capex only; opex handed to Operations)
A3: Area / category | B3: Floor area (m2) | C3: Rate (R/m2) | D3: Capex (R) | E3: Basis / source
A4: Production + storage hall | B4: =Space_Summary!B14-Space_Summary!B10-Space_Summary!B11-Space_Summary!B5 -> 957.59375 | C4: 8500 | D4: =B4*C4 -> 8139546.9 | E4: module lecture R/m2 indicative; verify quote
A5: Offices (admin) | B5: =Space_Summary!B10 -> 216 | C5: 12000 | D5: =B5*C5 -> 2592000 | E5: supplier-based estimate required
A6: Amenities (lockers, restrooms, cafeteria) | B6: =Space_Summary!B11 -> 203 | C6: 10000 | D6: =B6*C6 -> 2030000 | E6: supplier-based estimate required
A7: Powder-coat enclosure + extraction | B7: =Space_Summary!B5 -> 135 | C7: 18000 | D7: =B7*C7 -> 2430000 | E7: supplier-based; HVAC + fire suppression
A8: Parking + internal roads | B8: =Parking!B10 -> 2198 | C8: 1200 | D8: =B8*C8 -> 2637600 | E8: supplier-based estimate required
A9: Subtotal building | D9: =SUM(D4:D8) -> 17829147
A11: Equipment capex (supplier-based; quote required)
A12: Equipment | B12: Qty | C12: Indicative unit cost (R) | D12: Capex (R) | E12: Supplier-class source
A13: Automatic cold saw with bar feed (tube cut) | B13: =Capacity!M4 -> 2 | C13: 350000 | D13: =B13*C13 -> 700000 | E13: ProfiFeed A420 class; supplier quote
A14: Electric tapping machine (internal thread) | B14: =Capacity!M5 -> 2 | C14: 180000 | D14: =B14*C14 -> 360000 | E14: Roscamat Tiger class; supplier quote
A15: Ram-type tube end former (narrow end) | B15: =Capacity!M6 -> 1 | C15: 250000 | D15: =B15*C15 -> 250000 | E15: Hippo class; supplier quote
A16: Two-die thread/profile rolling machine (knurl + thread) | B16: =Capacity!M7 -> 4 | C16: 380000 | D16: =B16*C16 -> 1520000 | E16: Profimach PTR 42 class; supplier quote
A17: Power press, progressive die (shovel head stamp) | B17: =Capacity!M8 -> 1 | C17: 450000 | D17: =B17*C17 -> 450000 | E17: mechanical press class; supplier quote
A18: Press brake (shovel head shape/bend) | B18: =Capacity!M9 -> 1 | C18: 300000 | D18: =B18*C18 -> 300000 | E18: press brake class; supplier quote
A19: Automated grinder (blade sharpening, 8 units) | B19: =Capacity!M10 -> 8 | C19: 280000 | D19: =B19*C19 -> 2240000 | E19: automated grinder class; supplier quote
A20: Automated serrator (blade serrate, 4 units) | B20: =Capacity!M11 -> 4 | C20: 220000 | D20: =B20*C20 -> 880000 | E20: automated serrator class; supplier quote
A21: Power press, progressive die (hinge stamp) | B21: =Capacity!M12 -> 1 | C21: 280000 | D21: =B21*C21 -> 280000 | E21: mechanical press class; supplier quote
A22: Small press brake (hinge bend) | B22: =Capacity!M13 -> 1 | C22: 180000 | D22: =B22*C22 -> 180000 | E22: press brake class; supplier quote
A23: Pneumatic riveter | B23: =Capacity!M14 -> 1 | C23: 60000 | D23: =B23*C23 -> 60000 | E23: standard riveter class; supplier quote
A24: Polishing / deburring station (4 units) | B24: =Capacity!M15 -> 4 | C24: 120000 | D24: =B24*C24 -> 480000 | E24: buffing/deburring class; supplier quote
... A26: Packaging workstation (bench + tape + scale) | B26: =Capacity!M17 -> 2 | C26: 35000 | D26: =B26*C26 -> 70000 | E26: fitting bench + tooling
A27: T6 ageing batch oven | B27: ='Equipment-dep'!B15 -> 1 | C27: 950000 | D27: =B27*C27 -> 950000 | E27: ARC / aluminium ageing furnace class; supplier quote
A28: Sandblasting booth with extraction | B28: 1 | C28: 650000 | D28: =B28*C28 -> 650000 | E28: enclosed booth class; supplier quote
A29: Powder-coat conveyor + booth + cure oven | B29: ='Equipment-dep'!B9 -> 2 | C29: 2800000 | D29: =B29*C29 -> 5600000 | E29: conveyorised 600 parts/h line; supplier quote
A30: Counterbalance forklift (3 t) | B30: 3 | C30: 450000 | D30: =B30*C30 -> 1350000 | E30: standard 3 t forklift class
A31: Pallet jacks and trolleys | B31: 8 | C31: 18000 | D31: =B31*C31 -> 144000 | E31: standard MH
A32: Subtotal equipment | D32: =SUM(D13:D31) -> 16544000
A34: TOTAL ESTIMATED CAPEX (building + equipment) | D34: =D9+D32 -> 34373147
A36: Risk register
A37: Risk | B37: Likelihood | C37: Impact | D37: Score | E37: Mitigation
A38: Powder-coat enclosure construction delay | B38: High | C38: High | D38: 9 | E38: Phase build: powder line on critical path; pre-order long-lead extraction units; commission in parallel
A39: Equipment delivery lead time (heat-treat oven, powder line) | B39: Medium | C39: High | D39: 6 | E39: Place orders at design freeze; penalty clauses; identify alternate suppliers
A40: Aluminium price volatility | B40: High | C40: Medium | D40: 6 | E40: 6-month rolling supplier contracts; track LME; pass-through clause to customers
A41: Bottleneck stations under +10% demand growth | B41: Medium | C41: High | D41: 6 | E41: Reserve floor space adjacent to cut, knurl+thread and sharpen for +1 machine each; utilities sized at +20% margin
A42: Skilled operator shortage (threading, powder coat) | B42: Medium | C42: Medium | D42: 4 | E42: 8-week training programme; TVET partnership; OEM training during commissioning
A43: Regulatory approval (zoning, fume emissions) | B43: Low | C43: High | D43: 3 | E43: Municipality engagement at concept; environmental compliance certificate before slab pour
A44: Building cost overrun | B44: Medium | C44: Medium | D44: 4 | E44: Fixed-price contract with QS oversight; 10% capex contingency
A45: Forklift / pedestrian collision | B45: Medium | C45: High | D45: 6 | E45: Painted pedestrian lanes; mirrors at blind corners; speed governors; induction training
...

Sheet Traceability
A1: Traceability matrix: requirement -> design element -> evidence in report and MFP
A2: Audit aid for examiner. Every requirement must show a numeric link, a report section, and a visible MFP location.
A4: Req # | B4: Requirement (from brief) | C4: Design response | D4: Live figure | E4: Report section | F4: MFP zone | G4: Verified
A5: R1 | B5: Meet 400 000 shovels/yr | C5: 1 819 good shovels/day at 480 effective min | D5: =Demand!B6 -> 1819 | E5: 6.1, 6.4 | F5: entire production hall | G5: yes
A6: R2 | B6: Single 9 h shift, 220 workdays | C6: 480 effective min/day (60 min breaks) | D6: =Inputs!C10 -> 480 | E6: 6.3 | F6: scheduling assumption | G6: yes
A7: R3 | B7: 5% scrap on tube cut and sheet stamp only | C7: Cut/stamp grossed at 1 915/day; downstream cumulative | D7: =Capacity!G4 -> 3829.4737 | E7: 6.1, 6.4 | F7: scrap bin and waste store on MFP | G7: yes
A8: R4 | B8: Powder coating in enclosed area | C8: Dedicated enclosure with extraction, off finishing spine | D8: =Space_Summary!B5 -> 135 | E8: 6.5, 7 | F8: powder-coat block, hatched, with extraction arrow | G8: yes
A9: R5 | B9: 2 weeks raw material on hand | C9: 18 190 shovel-equivalents; tube + sheet | D9: =Inventory_Pack!B4 -> 18190 | E9: 6.2, 7 | F9: RM zone at receiving end | G9: yes
A10: R6 | B10: 4 weeks finished goods on hand | C10: 36 380 shovels; palletised, racked | D10: =Inventory_Pack!B5 -> 36380 | E10: 6.2, 7 | F10: FG zone at dispatch end | G10: yes
A11: R7 | B11: ~10% expansion provision (5 yr) | C11: 170 m2 reserved adjacent to bottleneck cells | D11: =Space_Summary!B15 -> 151 | E11: 7, 9 | F11: hatched expansion strip on MFP | G11: yes
A12: R8 | B12: Small order = on-site customer collection | C12: Retail collection point at dispatch face | D12: =Personnel!B17 -> 34 | E12: 6.5, 9 | F12: small-order pickup window | G12: yes
A13: R9 | B13: Large order = own truck fleet | C13: 6 truck bays on site | D13: =Parking!B8 -> 5 | E13: 6.5, 9 | F13: truck bays + manoeuvring apron | G13: yes
A14: R10 | B14: Heat treat + sandblast spaces | C14: Supplier-class oven + booth area | D14: =Space_Summary!B6 -> 70 | E14: 6.5 | F14: heat treat / sandblast block | G14: yes
A15: R11 | B15: At least 3 alternatives, weighted evaluation | C15: Linear, U-shape, parallel-branch; weighted scores | D15: =Evaluation!F11 -> 4.1 | E15: 7, 8 | F15: alternative block-layout figures | G15: yes
A16: R12 | B16: MFP with workstations, MH, storage, R&D, personnel | C16: Complete MFP, scaled, with flow arrows + dimensions | D16: =Space_Summary!B16 -> 1663 | E16: 9 | F16: whole MFP | G16: yes
A17: R13 | B17: Personnel + parking + amenities | C17: 60 headcount; 70 car bays + 6 truck bays; amenities sized | D17: =Personnel!B18 -> 58 | E17: 6.5, 9 | F17: employee + visitor + truck parking; amenities block | G17: yes
A18: R14 | B18: UK English; no AI references; assumptions labelled | C18: Style and integrity rules applied through report | D18: - | E18: whole report | F18: - | G18: yes
A19: R15 | B19: Two MFP files uploaded (drawio source + PDF) | C19: Draw.io source kept; PDF exported; A2 colour print | D19: - | E19: submission | F19: - | G19: pending upload
