Workbook

Sheet Inputs
A1: DigMore Folding Mini Shovel - Facility Design Calculations (single source of truth)
A2: Blue = input you can change; black = formula; green = link from another sheet. Yellow = key designer assumption to confirm.
B4: Parameter | C4: Value | D4: Unit | E4: Note / source
B5: Annual demand | C5: 400000 | D5: shovels/yr | E5: 2026 brief
B6: Workdays per year | C6: 220 | D6: days | E6: 2026 brief
B7: Daily demand (good) | C7: =ROUNDUP(C5/C6,0) -> 1819 | D7: shovels/day | E7: rounded up
B8: Shift length | C8: 540 | D8: min | E8: 9 h (brief)
B9: Breaks | C9: 60 | D9: min | E9: 30+15+15 (brief)
B10: Effective time | C10: =C8-C9 -> 480 | D10: min/day | E10: shift - breaks
B11: Availability allowance | C11: 0.9 | D11: fraction | E11: setup/changeover/stoppages
B12: Productive time / machine | C12: =C10*C11 -> 432 | D12: min/day | E12: effective x availability
B13: Takt time | C13: =ROUND(C10*60/C7,2) -> 15.83 | D13: s/shovel | E13: effective/daily demand
B14: Scrap rate (cut & stamp) | C14: 0.05 | D14: fraction | E14: brief (those two steps)
B15: Yield | C15: =1-C14 -> 0.95 | D15: fraction | E15: 1 - scrap
B16: Pipes per cut | C16: 1 | D16: pipes | E16: bundle cutting raises this
B17: Operators per machine | C17: 1 | D17: - | E17: baseline 1:1
B18: Packaging cycle (assumed) | C18: 30 | D18: s/shovel | E18: brief: workstation-dependent
B19: Tube stock length | C19: 6 | D19: m | E19: to verify with supplier
B20: Handle section length | C20: 0.15 | D20: m | E20: brief (150 mm)
B21: Sections per tube | C21: =FLOOR(C19/C20,1) -> 40 | D21: sections | E21: kerf ignored
B22: Tube sections per shovel | C22: 2 | D22: sections | E22: back + middle
B23: Sheet length | C23: 2.5 | D23: m | E23: standard sheet (assumption)
B24: Sheet width | C24: 1.25 | D24: m | E24: standard sheet (assumption)
B25: Nesting efficiency | C25: 0.75 | D25: fraction | E25: assumption
B26: Head blank length | C26: 0.17 | D26: m | E26: finished 150 + allowance (assumption)
B27: Head blank width | C27: 0.14 | D27: m | E27: finished 120 + allowance (assumption)
B28: Hinge blank length | C28: 0.08 | D28: m | E28: assumption
B29: Hinge blank width | C29: 0.05 | D29: m | E29: assumption
B30: Raw material cover | C30: 10 | D30: days | E30: 2 weeks (brief)
B31: Finished goods cover | C31: 20 | D31: days | E31: 4 weeks (brief)
B32: WIP buffer | C32: 1 | D32: days | E32: about one shift (assumption)
B33: Units per box | C33: 10 | D33: shovels | E33: assumption
B34: Boxes per pallet | C34: 40 | D34: boxes | E34: assumption
B35: Units per pallet | C35: =C33*C34 -> 400 | D35: shovels | E35: box x pallet
B36: Pallet length | C36: 1.2 | D36: m | E36: standard (assumption)
B37: Pallet width | C37: 1 | D37: m | E37: standard (assumption)
B38: Pallet footprint | C38: =C36*C37 -> 1.2 | D38: m2
B39: Storage levels (racking) | C39: 3 | D39: - | E39: assumption
B40: Tubes per cantilever rack | C40: 250 | D40: tubes | E40: assumption
B41: Cantilever rack footprint | C41: 6 | D41: m2 | E41: 6 m x 1 m (assumption)
...

Sheet Demand
A1: Demand and production requirement
A3: Measure | B3: Value | C3: Unit | D3: Basis
A4: Annual demand | B4: =Inputs!$C$5 -> 400000 | C4: shovels/yr | D4: brief
A5: Workdays | B5: =Inputs!$C$6 -> 220 | C5: days | D5: brief
A6: Daily demand (good) | B6: =Inputs!$C$7 -> 1819 | C6: shovels/day | D6: annual/days, round up
A7: Effective time | B7: =Inputs!$C$10 -> 480 | C7: min/day | D7: shift - breaks
A8: Hourly demand | B8: =Inputs!$C$7/(Inputs!$C$10/60) -> 227.375 | C8: shovels/h | D8: daily/effective hours
A9: Takt time | B9: =Inputs!$C$13 -> 15.83 | C9: s/shovel | D9: effective/daily
A11: Part-level daily requirement
A12: Part | B12: Per shovel | C12: Good/day | D12: Gross/day (if scrap step)
A13: Back handle section (tube) | B13: 1 | C13: =B13*Inputs!$C$7 -> 1819
A14: Middle handle section (tube) | B14: 1 | C14: =B14*Inputs!$C$7 -> 1819
A15: Handle sections cut (tube) | B15: 2 | C15: =B15*Inputs!$C$7 -> 3638 | D15: =C15/Inputs!$C$15 -> 3829.4737
A16: Shovel head (sheet) | B16: 1 | C16: =B16*Inputs!$C$7 -> 1819 | D16: =C16/Inputs!$C$15 -> 1914.7368
A17: Hinge connector (sheet) | B17: 1 | C17: =B17*Inputs!$C$7 -> 1819 | D17: =C17/Inputs!$C$15 -> 1914.7368

Sheet Capacity
A1: Per-process capacity: machines and operators
A3: Process | B3: Basis | C3: Units/shovel | D3: Scrap? | E3: Daily good | F3: Scrap factor | G3: Daily gross | H3: Pieces/op | I3: Ops/day | J3: Cycle (s) | K3: Time (min/day) | L3: Prod min/mach | M3: Machines | N3: Util. | O3: Operators | P3: Note
A4: Cut handle | B4: per cut | C4: 2 | D4: Yes | E4: =Inputs!$C$7*C4 -> 3638 | F4: =IF(D4="Yes",1/Inputs!$C$15,1) -> 1.0526316 | G4: =E4*F4 -> 3829.4737 | H4: =Inputs!$C$16 -> 1 | I4: =G4/H4 -> 3829.4737 | J4: 15 | K4: =I4*J4/60 -> 957.36842 | L4: =Inputs!$C$12 -> 432 | M4: =ROUNDUP(K4/L4,0) -> 3 | N4: =K4/(M4*L4) -> 0.7387102 | O4: =M4*Inputs!$C$17 -> 3 | P4: 5% scrap; pipes/cut from equipment
A5: Internal thread (middle) | B5: per pipe | C5: 1 | D5: No | E5: =Inputs!$C$7*C5 -> 1819 | F5: =IF(D5="Yes",1/Inputs!$C$15,1) -> 1 | G5: =E5*F5 -> 1819 | H5: 1 | I5: =G5/H5 -> 1819 | J5: 20 | K5: =I5*J5/60 -> 606.33333 | L5: =Inputs!$C$12 -> 432 | M5: =ROUNDUP(K5/L5,0) -> 2 | N5: =K5/(M5*L5) -> 0.70177469 | O5: =M5*Inputs!$C$17 -> 2 | P5: brief
A6: Stamp / narrow end (grip) | B6: per pipe | C6: 1 | D6: No | E6: =Inputs!$C$7*C6 -> 1819 | F6: =IF(D6="Yes",1/Inputs!$C$15,1) -> 1 | G6: =E6*F6 -> 1819 | H6: 1 | I6: =G6/H6 -> 1819 | J6: 5 | K6: =I6*J6/60 -> 151.58333 | L6: =Inputs!$C$12 -> 432 | M6: =ROUNDUP(K6/L6,0) -> 1 | N6: =K6/(M6*L6) -> 0.35088735 | O6: =M6*Inputs!$C$17 -> 1 | P6: brief
A7: Knurl + external thread (grip) | B7: per pipe | C7: 1 | D7: No | E7: =Inputs!$C$7*C7 -> 1819 | F7: =IF(D7="Yes",1/Inputs!$C$15,1) -> 1 | G7: =E7*F7 -> 1819 | H7: 1 | I7: =G7/H7 -> 1819 | J7: 60 | K7: =I7*J7/60 -> 1819 | L7: =Inputs!$C$12 -> 432 | M7: =ROUNDUP(K7/L7,0) -> 5 | N7: =K7/(M7*L7) -> 0.84212963 | O7: =M7*Inputs!$C$17 -> 5 | P7: thread rolling can cut this
A8: Stamp shovel head | B8: per part | C8: 1 | D8: Yes | E8: =Inputs!$C$7*C8 -> 1819 | F8: =IF(D8="Yes",1/Inputs!$C$15,1) -> 1.0526316 | G8: =E8*F8 -> 1914.7368 | H8: 1 | I8: =G8/H8 -> 1914.7368 | J8: 2 | K8: =I8*J8/60 -> 63.824561 | L8: =Inputs!$C$12 -> 432 | M8: =ROUNDUP(K8/L8,0) -> 1 | N8: =K8/(M8*L8) -> 0.14774204 | O8: =M8*Inputs!$C$17 -> 1 | P8: 5% scrap
A9: Shape / bend head | B9: per head | C9: 1 | D9: No | E9: =Inputs!$C$7*C9 -> 1819 | F9: =IF(D9="Yes",1/Inputs!$C$15,1) -> 1 | G9: =E9*F9 -> 1819 | H9: 1 | I9: =G9/H9 -> 1819 | J9: 2 | K9: =I9*J9/60 -> 60.633333 | L9: =Inputs!$C$12 -> 432 | M9: =ROUNDUP(K9/L9,0) -> 1 | N9: =K9/(M9*L9) -> 0.14035494 | O9: =M9*Inputs!$C$17 -> 1 | P9: brief
A10: Sharpen blade | B10: per shovel | C10: 1 | D10: No | E10: =Inputs!$C$7*C10 -> 1819 | F10: =IF(D10="Yes",1/Inputs!$C$15,1) -> 1 | G10: =E10*F10 -> 1819 | H10: 1 | I10: =G10/H10 -> 1819 | J10: 120 | K10: =I10*J10/60 -> 3638 | L10: =Inputs!$C$12 -> 432 | M10: =ROUNDUP(K10/L10,0) -> 9 | N10: =K10/(M10*L10) -> 0.93569959 | O10: =M10*Inputs!$C$17 -> 9 | P10: main bottleneck
A11: Serrate edge | B11: per shovel | C11: 1 | D11: No | E11: =Inputs!$C$7*C11 -> 1819 | F11: =IF(D11="Yes",1/Inputs!$C$15,1) -> 1 | G11: =E11*F11 -> 1819 | H11: 1 | I11: =G11/H11 -> 1819 | J11: 60 | K11: =I11*J11/60 -> 1819 | L11: =Inputs!$C$12 -> 432 | M11: =ROUNDUP(K11/L11,0) -> 5 | N11: =K11/(M11*L11) -> 0.84212963 | O11: =M11*Inputs!$C$17 -> 5 | P11: brief
A12: Stamp hinge connector | B12: per part | C12: 1 | D12: Yes | E12: =Inputs!$C$7*C12 -> 1819 | F12: =IF(D12="Yes",1/Inputs!$C$15,1) -> 1.0526316 | G12: =E12*F12 -> 1914.7368 | H12: 1 | I12: =G12/H12 -> 1914.7368 | J12: 2 | K12: =I12*J12/60 -> 63.824561 | L12: =Inputs!$C$12 -> 432 | M12: =ROUNDUP(K12/L12,0) -> 1 | N12: =K12/(M12*L12) -> 0.14774204 | O12: =M12*Inputs!$C$17 -> 1 | P12: 5% scrap
A13: Bend hinge connector | B13: per part | C13: 1 | D13: No | E13: =Inputs!$C$7*C13 -> 1819 | F13: =IF(D13="Yes",1/Inputs!$C$15,1) -> 1 | G13: =E13*F13 -> 1819 | H13: 1 | I13: =G13/H13 -> 1819 | J13: 5 | K13: =I13*J13/60 -> 151.58333 | L13: =Inputs!$C$12 -> 432 | M13: =ROUNDUP(K13/L13,0) -> 1 | N13: =K13/(M13*L13) -> 0.35088735 | O13: =M13*Inputs!$C$17 -> 1 | P13: brief
A14: Rivet hinge to head | B14: per shovel | C14: 1 | D14: No | E14: =Inputs!$C$7*C14 -> 1819 | F14: =IF(D14="Yes",1/Inputs!$C$15,1) -> 1 | G14: =E14*F14 -> 1819 | H14: 1 | I14: =G14/H14 -> 1819 | J14: 5 | K14: =I14*J14/60 -> 151.58333 | L14: =Inputs!$C$12 -> 432 | M14: =ROUNDUP(K14/L14,0) -> 1 | N14: =K14/(M14*L14) -> 0.35088735 | O14: =M14*Inputs!$C$17 -> 1 | P14: brief
A15: Hand polish / deburr | B15: per head | C15: 1 | D15: No | E15: =Inputs!$C$7*C15 -> 1819 | F15: =IF(D15="Yes",1/Inputs!$C$15,1) -> 1 | G15: =E15*F15 -> 1819 | H15: 1 | I15: =G15/H15 -> 1819 | J15: 60 | K15: =I15*J15/60 -> 1819 | L15: =Inputs!$C$12 -> 432 | M15: =ROUNDUP(K15/L15,0) -> 5 | N15: =K15/(M15*L15) -> 0.84212963 | O15: =M15*Inputs!$C$17 -> 5 | P15: brief
A16: Final assembly | B16: per shovel | C16: 1 | D16: No | E16: =Inputs!$C$7*C16 -> 1819 | F16: =IF(D16="Yes",1/Inputs!$C$15,1) -> 1 | G16: =E16*F16 -> 1819 | H16: 1 | I16: =G16/H16 -> 1819 | J16: 30 | K16: =I16*J16/60 -> 909.5 | L16: =Inputs!$C$12 -> 432 | M16: =ROUNDUP(K16/L16,0) -> 3 | N16: =K16/(M16*L16) -> 0.70177469 | O16: =M16*Inputs!$C$17 -> 3 | P16: brief
A17: Packaging (hand + check) | B17: per shovel | C17: 1 | D17: No | E17: =Inputs!$C$7*C17 -> 1819 | F17: =IF(D17="Yes",1/Inputs!$C$15,1) -> 1 | G17: =E17*F17 -> 1819 | H17: 1 | I17: =G17/H17 -> 1819 | J17: =Inputs!$C$18 -> 30 | K17: =I17*J17/60 -> 909.5 | L17: =Inputs!$C$12 -> 432 | M17: =ROUNDUP(K17/L17,0) -> 3 | N17: =K17/(M17*L17) -> 0.70177469 | O17: =M17*Inputs!$C$17 -> 3 | P17: cycle is an assumption
A18: TOTAL (line processes) | M18: =SUM(M4:M17) -> 41 | O18: =SUM(O4:O17) -> 41

Sheet Equipment-dep
A1: Equipment-dependent processes (no brief cycle time)
A3: Powder coating (conveyorised, enclosed)
A5: Coated items per day | B5: =Inputs!$C$7*Inputs!$C$46 -> 5457 | C5: items/day
A6: Assumed line rate | B6: =Inputs!$C$45 -> 600 | C6: parts/h
A7: Hours needed | B7: =B5/B6 -> 9.095 | C7: h/day
A8: Productive hours/shift | B8: =Inputs!$C$12/60 -> 7.2 | C8: h
A9: Powder lines required | B9: =ROUNDUP(B7/B8,0) -> 2 | C9: lines
A10: At 600 parts/h the line exceeds one shift; ~760 parts/h or a second line needed.
A12: Heat treatment (T6 ageing, batch oven)
A13: Subassemblies per day | B13: =Inputs!$C$7 -> 1819 | C13: items/day
A14: Assumed cycle | B14: =Inputs!$C$44 -> 6 | C14: h/batch
A15: Ageing ovens (assumed) | B15: 1 | C15: ovens
A16: Oven sized to ~1 day of subassemblies; runs across/after the shift. Supplier-based; verify.
A18: Sandblasting (enclosed booth)
A19: Heads per day | B19: =Inputs!$C$7 -> 1819 | C19: items/day
A20: Throughput and booth count: supplier-based estimate required.

Sheet RawMaterials
A1: Raw material requirements
A3: Aluminium round tube
A4: Sections per shovel | B4: =Inputs!$C$22 -> 2 | C4: sections
A5: Good sections/day | B5: =Inputs!$C$7*B4 -> 3638 | C5: sections/day
A6: Gross sections/day (scrap) | B6: =B5/Inputs!$C$15 -> 3829.4737 | C6: sections/day
A7: Sections per 6 m tube | B7: =Inputs!$C$21 -> 40 | C7: sections
A8: Tubes per day | B8: =ROUNDUP(B6/B7,0) -> 96 | C8: tubes/day
A9: Tubes for 2 weeks | B9: =B8*Inputs!$C$30 -> 960 | C9: tubes
A11: Aluminium sheet
A12: Sheet area | B12: =Inputs!$C$23*Inputs!$C$24 -> 3.125 | C12: m2
A13: Head blank area | B13: =Inputs!$C$26*Inputs!$C$27 -> 0.0238 | C13: m2
A14: Hinge blank area | B14: =Inputs!$C$28*Inputs!$C$29 -> 0.004 | C14: m2
A15: Heads per sheet (nested) | B15: =FLOOR(B12*Inputs!$C$25/B13,1) -> 98 | C15: parts
A16: Hinges per sheet (nested) | B16: =FLOOR(B12*Inputs!$C$25/B14,1) -> 585 | C16: parts
A17: Gross heads/day | B17: =Inputs!$C$7/Inputs!$C$15 -> 1914.7368 | C17: parts/day
A18: Gross hinges/day | B18: =Inputs!$C$7/Inputs!$C$15 -> 1914.7368 | C18: parts/day
A19: Sheets/day (heads) | B19: =ROUNDUP(B17/B15,0) -> 20 | C19: sheets/day
A20: Sheets/day (hinges) | B20: =ROUNDUP(B18/B16,0) -> 4 | C20: sheets/day
A21: Total sheets/day | B21: =B19+B20 -> 24 | C21: sheets/day
A22: Sheets for 2 weeks | B22: =B21*Inputs!$C$30 -> 240 | C22: sheets

Sheet Inventory_Pack
A1: Inventory levels and packaging unit loads
A3: Inventory (shovel-equivalents)
A4: Raw material on hand (2 wk) | B4: =Inputs!$C$30*Inputs!$C$7 -> 18190 | C4: shovels
A5: Finished goods (4 wk) | B5: =Inputs!$C$31*Inputs!$C$7 -> 36380 | C5: shovels
A6: WIP buffer (~1 shift) | B6: =Inputs!$C$32*Inputs!$C$7 -> 1819 | C6: shovels
A8: Packaging and order definitions
A9: Units per box | B9: =Inputs!$C$33 -> 10 | C9: shovels
A10: Boxes per pallet | B10: =Inputs!$C$34 -> 40 | C10: boxes
A11: Units per pallet | B11: =Inputs!$C$35 -> 400 | C11: shovels
A12: Boxes per day | B12: =ROUNDUP(Inputs!$C$7/Inputs!$C$33,0) -> 182 | C12: boxes/day
A13: Pallets per day | B13: =ROUNDUP(Inputs!$C$7/Inputs!$C$35,0) -> 5 | C13: pallets/day
A14: Small order (<= 1 pallet) | B14: =Inputs!$C$35 -> 400 | C14: shovels max
A15: Large order (> 1 pallet) | B15: >Inputs!$C$35 | C15: shovels

Sheet Storage_3D
A1: Storage sizing (3D footprint)
A3: Store | B3: Items | C3: Racks/positions | D3: Floor area (m2) | E3: Basis
A4: Raw tube | B4: =RawMaterials!B9 -> 960 | C4: =ROUNDUP(RawMaterials!B9/Inputs!$C$40,0) -> 4 | D4: =C4*Inputs!$C$41*Inputs!$C$43 -> 38.4 | E4: cantilever racks
A5: Raw sheet | B5: =RawMaterials!B22 -> 240 | C5: =ROUNDUP(RawMaterials!B22/Inputs!$C$42,0) -> 2 | D5: =C5*(Inputs!$C$23*Inputs!$C$24)*Inputs!$C$43 -> 10 | E5: sheet stacks
A6: Finished goods | B6: =ROUNDUP(Inventory_Pack!B5/Inputs!$C$35,0) -> 91 | C6: =ROUNDUP(B6/Inputs!$C$39,0) -> 31 | D6: =C6*Inputs!$C$38*Inputs!$C$43 -> 59.52 | E6: palletised, racked
A7: WIP staging | B7: =ROUNDUP(Inventory_Pack!B6/Inputs!$C$35,0) -> 5 | C7: =ROUNDUP(B7/Inputs!$C$39,0) -> 2 | D7: =C7*Inputs!$C$38*Inputs!$C$43 -> 3.84 | E7: decoupling buffers
A8: Scrap / waste | B8: - | C8: - | D8: =Inputs!$C$52 -> 40 | E8: assumption
A9: Total storage area | D9: =SUM(D4:D8) -> 151.76

Sheet Personnel
A1: Personnel (headcount)
A3: Category / role | B3: Number | C3: Note
A4: Senior Plant Manager | B4: 1 | C4: brief
A5: Operations Manager | B5: 1 | C5: brief
A6: Inventory Manager | B6: 1 | C6: brief
A7: Reception | B7: 1 | C7: brief
A8: Purchasing | B8: 1 | C8: brief
A9: Sales | B9: 2 | C9: brief (assumed count)
A10: Finance | B10: 1 | C10: brief
A11: Marketing | B11: 1 | C11: brief
A12: Human Resources | B12: 1 | C12: brief
A13: Plant supervisors | B13: 4 | C13: ~1 per dept (assumption)
A14: Security | B14: 3 | C14: assumption
A15: Material handlers / forklift | B15: 5 | C15: assumption
A16: Equipment-dep & QA operators | B16: 4 | C16: heat/sandblast/powder/inspection (assumption)
A17: Production operators (from Capacity) | B17: =Capacity!O18 -> 41 | C17: line processes, 1:1
A18: TOTAL headcount | B18: =SUM(B4:B17) -> 67

Sheet Parking
A1: Parking and site vehicle provision
A3: Total on-site headcount | B3: =Personnel!B18 -> 67 | C3: people
A4: Employee bays | B4: =B3*Inputs!$C$56 -> 67 | C4: bays
A5: Visitor + collection bays | B5: =Inputs!$C$57 -> 10 | C5: bays
A6: Total car bays | B6: =B4+B5 -> 77 | C6: bays
A7: Car parking area | B7: =B6*Inputs!$C$58 -> 1925 | C7: m2
A8: Truck fleet bays | B8: =Inputs!$C$59 -> 6 | C8: bays
A9: Truck fleet area | B9: =B8*Inputs!$C$60 -> 360 | C9: m2
A10: Total vehicle area | B10: =B7+B9 -> 2285 | C10: m2

Sheet Space_Summary
A1: Space summary and total footprint
A3: Area / department | B3: Floor area (m2) | C3: Basis
A4: Production workstations | B4: =Capacity!M18*Inputs!$C$47 -> 246 | C4: machines x area/workstation
A5: Powder coating (enclosed) | B5: =Inputs!$C$50 -> 120 | C5: supplier-based estimate
A6: Heat treat + sandblast | B6: =Inputs!$C$51 -> 80 | C6: supplier-based estimate
A7: Raw material + WIP + scrap storage | B7: =Storage_3D!D4+Storage_3D!D5+Storage_3D!D7+Storage_3D!D8 -> 92.24 | C7: from Storage_3D
A8: Finished goods storage | B8: =Storage_3D!D6 -> 59.52 | C8: from Storage_3D
A9: Receiving + dispatch | B9: =Inputs!$C$53 -> 250 | C9: docks + staging (assumption)
A10: Offices | B10: =(Personnel!B18-Capacity!O18)*Inputs!$C$54 -> 260 | C10: non-operator staff x area/person
A11: Amenities (lockers/restrooms/cafeteria) | B11: =Personnel!B18*Inputs!$C$55 -> 268 | C11: headcount x area/person
A12: Subtotal (functional floor) | B12: =SUM(B4:B11) -> 1375.76
A13: Circulation / aisles | B13: =B12*Inputs!$C$48 -> 412.728 | C13: allowance
A14: Building subtotal | B14: =B12+B13 -> 1788.488
A15: Future expansion (~10%) | B15: =B14*Inputs!$C$49 -> 178.8488
A16: TOTAL BUILDING | B16: =B14+B15 -> 1967.3368
A18: Parking + truck fleet (site) | B18: =Parking!B10 -> 2285 | C18: from Parking
A19: INDICATIVE SITE FOOTPRINT | B19: =B16+B18 -> 4252.3368

Sheet Machinery
A1: Recommended machinery (types and sources; dimensions/cost supplier-based)
A3: Process / area | B3: Recommended type | C3: Throughput / source note | D3: Dimensions | E3: Cost | F3: Status
A4: Cut handle | B4: Automatic non-ferrous cold saw, auto bar-feed, bundle cutting | C4: bundle cutting available (Addison Saws; Profifeed A550) | D4: supplier | E4: quote | F4: verify
A5: Threads + knurl | B5: Thread-rolling machine + knurling head | C5: 15-60+ parts/min (PowerTransmission; IQS) | D5: supplier | E5: quote | F5: verify
A6: Stamping (head/hinge/narrow) | B6: Mechanical power press + progressive die | C6: standard | D6: supplier | E6: quote | F6: verify
A7: Bending | B7: Press brake | C7: standard | D7: supplier | E7: quote | F7: verify
A8: Sharpen / serrate | B8: Automated grinding / serrating machine | C8: replaces 2 min / 1 min manual | D8: supplier | E8: quote | F8: verify
A9: Rivet | B9: Pneumatic / hydraulic riveter | C9: standard | D9: supplier | E9: quote | F9: verify
A10: Heat treat | B10: T6 artificial-ageing batch oven | C10: 5-8 h cycle (ARC; Aluminium-guide) | D10: supplier | E10: quote | F10: verify
A11: Sandblast | B11: Enclosed blast booth + extraction | C11: equipment-dependent | D11: supplier | E11: quote | F11: verify
A12: Powder coat | B12: Conveyorised powder line (booth + oven) | C12: ~600 parts/h; cure ~10-20 min (TheFabricator) | D12: supplier | E12: quote | F12: verify
A13: Assembly / packaging | B13: Manual workstations | C13: by hand + visual check (brief) | D13: - | E13: - | F13: stations from Capacity
A15: No machine dimensions or costs are invented; obtain from supplier quotations.

Sheet Evaluation
A1: Alternatives evaluation matrix (template - scores to be filled for 3 layouts)
A3: Criterion (from brief) | B3: Weight | C3: Alt 1 score | D3: Alt 2 score | E3: Alt 3 score | F3: Alt1 wtd | G3: Alt2 wtd | H3: Alt3 wtd
A4: Meets demand of 400 000/yr | B4: 0.2 | F4: =B4*C4 -> 0 | G4: =B4*D4 -> 0 | H4: =B4*E4 -> 0
A5: Logical material flow (receiving to dispatch) | B5: 0.2 | F5: =B5*C5 -> 0 | G5: =B5*D5 -> 0 | H5: =B5*E5 -> 0
A6: Enclosed powder coating + hazard separation | B6: 0.15 | F6: =B6*C6 -> 0 | G6: =B6*D6 -> 0 | H6: =B6*E6 -> 0
A7: Efficient storage and material handling | B7: 0.15 | F7: =B7*C7 -> 0 | G7: =B7*D7 -> 0 | H7: =B7*E7 -> 0
A8: Pedestrian / vehicle safety and site access | B8: 0.1 | F8: =B8*C8 -> 0 | G8: =B8*D8 -> 0 | H8: =B8*E8 -> 0
A9: ~10% expansion provision | B9: 0.1 | F9: =B9*C9 -> 0 | G9: =B9*D9 -> 0 | H9: =B9*E9 -> 0
A10: Ease of construction / implementation | B10: 0.1 | F10: =B10*C10 -> 0 | G10: =B10*D10 -> 0 | H10: =B10*E10 -> 0
A11: TOTAL | B11: =SUM(B4:B10) -> 1 | F11: =SUM(F4:F10) -> 0 | G11: =SUM(G4:G10) -> 0 | H11: =SUM(H4:H10) -> 0
A13: Enter a score of 1 (poor) to 5 (excellent) for each alternative; weighted totals rank the layouts.
