Workbook

Sheet Costs
A1: Component | B1: Rate (R/ m2) | C1: Total m2 | D1: Cost
A2: Building | B2: 7000 | C2: 21625 | D2: =B2*C2 -> 151375000 | F2: 108125000
A3: Offices | B3: 10000 | C3: 350 | D3: =B3*C3 -> 3500000
A4: Cafeteria | B4: 10000 | C4: 460 | D4: =B4*C4 -> 4600000
A5: Parking & Roads | B5: 1000 | C5: 6145 | D5: =B5*C5 -> 6145000
A6: Restrooms | B6: 7500 | C6: 385 | D6: =B6*C6 -> 2887500
A7: Electrical | B7: 1500 | C7: 22000 | D7: =B7*C7 -> 33000000
A8: Lighting | B8: 1000 | C8: 21625 | D8: =B8*C8 -> 21625000
A9: Ventilation | B9: 1000 | C9: 21625 | D9: =B9*C9 -> 21625000
A10: Fire Safety | B10: 300 | C10: 22000 | D10: =B10*C10 -> 6600000
A11: Equipment | D11: =D26 -> 92755000
A12: Total | D12: =SUM(D2:D11) -> 344112500
A15: Equipment | B15: Rate (R/ equipment) | C15: No. of equipment | D15: Cost
A16: Storage Racks | B16: 50000 | C16: 28 | D16: =B16*C16 -> 1400000
A17: Model 450 Netting | B17: 175000 | C17: 20 | D17: =B17*C17 -> 3500000
A18: Model 300 Netting | B18: 100000 | C18: 15 | D18: =B18*C18 -> 1500000
A19: Galvaniser | B19: 7000000 | C19: 7 | D19: =B19*C19 -> 49000000
A20: Hexagonal Netting | B20: 300000 | C20: 49 | D20: =B20*C20 -> 14700000
A21: Welded Mesh Netting | B21: 150000 | C21: 10 | D21: =B21*C21 -> 1500000
A22: Packaging Machine | B22: 75000 | C22: 97 | D22: =B22*C22 -> 7275000
A23: Workbenches | B23: 20000 | C23: 4 | D23: =B23*C23 -> 80000
A24: Electric Forklifts | B24: 400000 | C24: 24 | D24: =B24*C24 -> 9600000
A25: Pallet Jacks | B25: 35000 | C25: 120 | D25: =B25*C25 -> 4200000
D26: =SUM(D16:D25) -> 92755000

Sheet Storage
A1: Product | B1: Height of roll (m) | C1: Aperture (mm) | D1: Wire Diameter (m) | E1: Roll length (m) | F1: Roll Width (m) | G1: Weight per roll (kg) | H1: Galvinized finish | I1: Customer requirements per annum (kg)
A2: Bird Netting | B2: 0.9 | C2: 13 | D2: 0.0006 | E2: 50 | F2: 0.25 | G2: 22.5 | H2: Light | I2: 4000000
A3: Chicken Netting | B3: 1.8 | C3: 25 | D3: 0.0009 | E3: 50 | F3: 0.28 | G3: 41.9 | H3: Light | I3: 5500000
A4: Jackal Netting | B4: 0.6 | C4: 75 | D4: 0.0018 | E4: 50 | F4: 0.37 | G4: 19.5 | H4: Light | I4: 2500000
A5: Pig Netting | B5: 0.9 | C5: 90 | D5: 0.0018 | E5: 30 | F5: 0.29 | G5: 14.7 | H5: Light | I5: 8000000
A6: Welded Mesh | B6: 2 | C6: 50 | D6: 0.0025 | E6: 30 | F6: 0.34 | G6: 70 | H6: Heavy | I6: 6000000
A7: Totals
B9: Rolls produced per day | C9: Small order rolls | D9: Area needed for one roll | E9: Total area of daily rolls (sqm) | F9: Weekly storage space needed (sqm) | G9: Pallets | H9: 220
A10: Bird Netting | B10: =I2/G2/$H$9 -> 808.08081 | C10: =ROUNDUP(B10/10,0) -> 81 | D10: =B2*F2 -> 0.225 | E10: =C10/4*D10 -> 4.55625 | F10: =E10*7 -> 31.89375 | G10: =C10/16 -> 5.0625
A11: Chicken Netting | B11: =I3/G3/$H$9 -> 596.65871 | C11: =ROUNDUP(B11/10,0) -> 60 | D11: =B3*F3 -> 0.504 | E11: =C11/4*D11 -> 7.56 | F11: =E11*7 -> 52.92 | G11: =C11/16 -> 3.75
A12: Jackal Netting | B12: =I4/G4/$H$9 -> 582.75058 | C12: =ROUNDUP(B12/10,0) -> 59 | D12: =B4*F4 -> 0.222 | E12: =C12/4*D12 -> 3.2745 | F12: =E12*7 -> 22.9215 | G12: =C12/16 -> 3.6875
A13: Pig Netting | B13: =I5/G5/$H$9 -> 2473.7168 | C13: =ROUNDUP(B13/10,0) -> 248 | D13: =B5*F5 -> 0.261 | E13: =C13/4*D13 -> 16.182 | F13: =E13*7 -> 113.274 | G13: =C13/16 -> 15.5
A14: Welded Mesh | B14: =I6/G6/$H$9 -> 389.61039 | C14: =ROUNDUP(B14/10,0) -> 39 | D14: =B6*F6 -> 0.68 | E14: =C14/4*D14 -> 6.63 | F14: =E14*7 -> 46.41 | G14: =C14/16 -> 2.4375
A15: Totals | B15: =SUM(B10:B14) -> 4850.8173 | C15: =SUM(C10:C14) -> 487 | D15: =SUM(D10:D14) -> 1.892 | E15: =SUM(E10:E14) -> 38.20275 | F15: =SUM(F10:F14) -> 267.41925 | G15: =C15/16 -> 30.4375
B17: Rolls produced per day | C17: Large order rolls | D17: =D9 -> Area needed for one roll | E17: Total area of daily rolls (sqm) | F17: Weekly storage space needed (sqm) | G17: Pallets
A18: Bird Netting | B18: =B10 -> 808.08081 | C18: =ROUNDUP(B18*0.9,0) -> 728 | D18: =D10 -> 0.225 | E18: =C18/4*D18 -> 40.95 | F18: =E18*2 -> 81.9 | G18: =C18/16/4 -> 11.375
A19: Chicken Netting | B19: =B11 -> 596.65871 | C19: =ROUNDUP(B19*0.9,0) -> 537 | D19: =D11 -> 0.504 | E19: =C19/4*D19 -> 67.662 | F19: =E19*2 -> 135.324 | G19: =C19/16/4 -> 8.390625
A20: Jackal Netting | B20: =B12 -> 582.75058 | C20: =ROUNDUP(B20*0.9,0) -> 525 | D20: =D12 -> 0.222 | E20: =C20/4*D20 -> 29.1375 | F20: =E20*2 -> 58.275 | G20: =C20/16/4 -> 8.203125
A21: Pig Netting | B21: =B13 -> 2473.7168 | C21: =ROUNDUP(B21*0.9,0) -> 2227 | D21: =D13 -> 0.261 | E21: =C21/4*D21 -> 145.31175 | F21: =E21*2 -> 290.6235 | G21: =C21/16/4 -> 34.796875
A22: Welded Mesh | B22: =B14 -> 389.61039 | C22: =ROUNDUP(B22*0.9,0) -> 351 | D22: =D14 -> 0.68 | E22: =C22/4*D22 -> 59.67 | F22: =E22*2 -> 119.34 | G22: =C22/16/4 -> 5.484375
A23: Totals | B23: =B15 -> 4850.8173 | C23: =ROUNDUP(B23*0.9,0) -> 4366 | D23: =D15 -> 1.892 | E23: =SUM(E18:E22) -> 342.73125 | F23: =SUM(F18:F22) -> 685.4625 | G23: =C23/16 -> 272.875

Sheet Storage Appendix
A1: Sto

Sheet Operation A
A1: Product | B1: Height of roll (m) | C1: Aperture (mm) | D1: Wire Diameter (m) | E1: Roll length (m) | F1: Weight per roll (kg) | G1: Galvinized finish | H1: Demand per annum (tons)
A2: Bird Netting | B2: 0.9 | C2: 13 | D2: 0.0006 | E2: 50 | F2: 22.5 | G2: Light | H2: 4000
A3: Chicken Netting | B3: 1.8 | C3: 25 | D3: 0.0009 | E3: 50 | F3: 41.9 | G3: Light | H3: 5500
A4: Jackal Netting | B4: 0.6 | C4: 75 | D4: 0.0018 | E4: 50 | F4: 19.5 | G4: Light | H4: 2500
A5: Pig Netting | B5: 0.9 | C5: 90 | D5: 0.0018 | E5: 30 | F5: 14.7 | G5: Light | H5: 8000
A6: Welded Mesh | B6: 2 | C6: 50 | D6: 0.0025 | E6: 30 | F6: 70 | G6: Heavy | H6: 6000
A7: Totals | H7: =SUM(H2:H6) -> 26000 | J7: =H7*1000/220 -> 118181.82
A10: Weight of steel wire coil | B10: 2500 | F10: https://aswonline.com.au/product/industrial-bright-wire-coil-5mm-x-1000kg/
A12: Length of raw material coil (m) | B12: 7000 | C12: Original diameter (m) | D12: 0.005
B14: Length of coil on exit (m) | C14: Weight per meter (kg) | D14: Metres per roll | E14: Rolls per annum | F14: m needed per annum | G14: km needed per annum | I14: =F25 -> 3682659.9 | J14: =C15 -> 0.0051428571 | K14: =I14*J14 -> 18939.394
A15: Bird Netting | B15: =((($D$12/2)^2)*$B$12)/((D2/2)^2) -> 486111.11 | C15: =$B$10/B15 -> 0.0051428571 | D15: =F2/C15 -> 4375 | E15: =H2*1000/F2 -> 177777.78 | F15: =D15*E15 -> 7.7777778e+08 | G15: =F15/1000 -> 777777.78 | I15: =F26 -> 2250514.4 | J15: =C16 -> 0.011571429 | K15: =I15*J15 -> 26041.667
A16: Chicken Netting | B16: =((($D$12/2)^2)*$B$12)/((D3/2)^2) -> 216049.38 | C16: =$B$10/B16 -> 0.011571429 | D16: =F3/C16 -> 3620.9877 | E16: =H3*1000/F3 -> 131264.92 | F16: =D16*E16 -> 4.7530864e+08 | G16: =F16/1000 -> 475308.64 | I16: =F27 -> 255740.27 | J16: =C17 -> 0.046285714 | K16: =I16*J16 -> 11837.121
A17: Jackal Netting | B17: =((($D$12/2)^2)*$B$12)/((D4/2)^2) -> 54012.346 | C17: =$B$10/B17 -> 0.046285714 | D17: =F4/C17 -> 421.2963 | E17: =H4*1000/F4 -> 128205.13 | F17: =D17*E17 -> 54012346 | G17: =F17/1000 -> 54012.346 | I17: =F28 -> 818368.87 | J17: =C18 -> 0.046285714 | K17: =I17*J17 -> 37878.788
A18: Pig Netting | B18: =((($D$12/2)^2)*$B$12)/((D5/2)^2) -> 54012.346 | C18: =$B$10/B18 -> 0.046285714 | D18: =F5/C18 -> 317.59259 | E18: =H5*1000/F5 -> 544217.69 | F18: =D18*E18 -> 1.7283951e+08 | G18: =F18/1000 -> 172839.51 | I18: =F29 -> 318181.82 | J18: =C19 -> 0.089285714 | K18: =I18*J18 -> 28409.091
A19: Welded Mesh | B19: =((($D$12/2)^2)*$B$12)/((D6/2)^2) -> 28000 | C19: =$B$10/B19 -> 0.089285714 | D19: =F6/C19 -> 784 | E19: =H6*1000/F6 -> 85714.286 | F19: =D19*E19 -> 67200000 | G19: =F19/1000 -> 67200 | K19: =SUM(K14:K18) -> 123106.06
A20: Total | B20: =SUM(B15:B19) -> 838185.19 | C20: =SUM(C15:C19) -> 0.19857143 | D20: =SUM(D15:D19) -> 9518.8765 | E20: =SUM(E15:E19) -> 1067179.8 | F20: =SUM(F15:F19) -> 1.5471383e+09 | G20: =SUM(G15:G19) -> 1547138.3
A22: Days worked per day | B22: 220
B23: After draw | D23: Before draw | F23: With 4% scrap allowance (after draw) | H23: With 4% scrap allowance (before draw)
B24: m per day | C24: km per day | D24: m per day | E24: km per day | F24: m per day | G24: km per day | H24: m per day | I24: km per day
A25: Bird Netting | B25: =F15/$B$22 -> 3535353.5 | C25: =B25/1000 -> 3535.3535 | D25: =(((D2/2)^2)*B25)/(($D$12/2)^2) -> 50909.091 | E25: =D25/1000 -> 50.909091 | F25: =B25/0.96 -> 3682659.9 | G25: =F25/1000 -> 3682.6599 | H25: =D25/0.96 -> 53030.303 | I25: =H25/1000 -> 53.030303
A26: Chicken Netting | B26: =F16/$B$22 -> 2160493.8 | C26: =B26/1000 -> 2160.4938 | D26: =(((D3/2)^2)*B26)/(($D$12/2)^2) -> 70000 | E26: =D26/1000 -> 70 | F26: =B26/0.96 -> 2250514.4 | G26: =F26/1000 -> 2250.5144 | H26: =D26/0.96 -> 72916.667 | I26: =H26/1000 -> 72.916667
A27: Jackal Netting | B27: =F17/$B$22 -> 245510.66 | C27: =B27/1000 -> 245.51066 | D27: =(((D4/2)^2)*B27)/(($D$12/2)^2) -> 31818.182 | E27: =D27/1000 -> 31.818182 | F27: =B27/0.96 -> 255740.27 | G27: =F27/1000 -> 255.74027 | H27: =D27/0.96 -> 33143.939 | I27: =H27/1000 -> 33.143939
A28: Pig Netting | B28: =F18/$B$22 -> 785634.12 | C28: =B28/1000 -> 785.63412 | D28: =(((D5/2)^2)*B28)/(($D$12/2)^2) -> 101818.18 | E28: =D28/1000 -> 101.81818 | F28: =B28/0.96 -> 818368.87 | G28: =F28/1000 -> 818.36887 | H28: =D28/0.96 -> 106060.61 | I28: =H28/1000 -> 106.06061
A29: Welded Mesh | B29: =F19/$B$22 -> 305454.55 | C29: =B29/1000 -> 305.45455 | D29: =(((D6/2)^2)*B29)/(($D$12/2)^2) -> 76363.636 | E29: =D29/1000 -> 76.363636 | F29: =B29/0.96 -> 318181.82 | G29: =F29/1000 -> 318.18182 | H29: =D29/0.96 -> 79545.455 | I29: =H29/1000 -> 79.545455
A30: Total | B30: =SUM(B25:B29) -> 7032446.7 | C30: =SUM(C25:C29) -> 7032.4467 | D30: =SUM(D25:D29) -> 330909.09 | E30: =SUM(E25:E29) -> 330.90909 | F30: =SUM(F25:F29) -> 7325465.3 | G30: =SUM(G25:G29) -> 7325.4653 | H30: =SUM(H25:H29) -> 344696.97 | I30: =SUM(I25:I29) -> 344.69697
B32: Daily Production Requirement (m) | C32: Drawing Speed (m/s) | D32: Drawing Speed machine 2 | E32: Length one machine draws per day | F32: No. of machines needed
A33: Bird Netting | B33: =F25 -> 3682659.9 | C33: 15 | D33: 15 | E33: =C33*60*60*7 -> 378000 | F33: =ROUNDUP(B33/E33,0)*2 -> 20
A34: Chicken Netting | B34: =F26 -> 2250514.4 | C34: 15 | D34: 15 | E34: =C34*60*60*7 -> 378000 | F34: =ROUNDUP(B34/E34,0)*2 -> 12 | H34: =F30*220 -> 1.6116024e+09
A35: Jackal Netting | B35: =F27 -> 255740.27 | C35: 20 | D35: - | E35: =C35*60*60*7 -> 504000 | F35: =ROUNDUP(B35/E35,0) -> 1 | H35: =H30*220 -> 75833333
A36: Pig Netting | B36: =F28 -> 818368.87 | C36: 20 | D36: - | E36: =C36*60*60*7 -> 504000 | F36: =ROUNDUP(B36/E36,0) -> 2
A37: Welded Mesh | B37: =F29 -> 318181.82 | C37: 20 | D37: - | E37: =C37*60*60*7 -> 504000 | F37: =ROUNDUP(B37/E37,0) -> 1
A38: Total | B38: =SUM(B33:B37) -> 7325465.3 | C38: =SUM(C33:C37) -> 90 | E38: =SUM(E33:E37) -> 2268000 | F38: =SUM(F33:F37) -> 36
E39: *use for 7hrs per day (1hr cleaning and setup time)
A41: No. of raw material coils needed | B41: =H30/7000 -> 49.242424
A42: No. of raw material coils in storage (3 days) | B42: =B41*3 -> 147.72727
B46: Height of roll (m) | C46: Roll length (m) | D46: Material thickness (m)
A47: Bird Netting | B47: 0.9 | C47: 50 | D47: =D2+0.0002 -> 0.0008
A48: Chicken Netting | B48: 1.8 | C48: 50 | D48: =D3+0.0002 -> 0.0011
A49: Jackal Netting | B49: 0.6 | C49: 50 | D49: =D4+0.0002 -> 0.002
A50: Pig Netting | B50: 0.9 | C50: 30 | D50: =D5+0.0002 -> 0.002
...

Sheet Op.A Appendix
A1: Product | B1: Height of roll (m) | C1: Aperture (mm) | D1: Wire Diameter (m) | E1: Roll length (m) | F1: Weight per roll (kg) | G1: Galvinized finish | H1: Demand per annum (tons)
A2: Bird Netting | B2: 0.9 | C2: 13 | D2: 0.0006 | E2: 50 | F2: 22.5 | G2: Light | H2: 4000
A3: Chicken Netting | B3: 1.8 | C3: 25 | D3: 0.0009 | E3: 50 | F3: 41.9 | G3: Light | H3: 5500
A4: Jackal Netting | B4: 0.6 | C4: 75 | D4: 0.0018 | E4: 50 | F4: 19.5 | G4: Light | H4: 2500
A5: Pig Netting | B5: 0.9 | C5: 90 | D5: 0.0018 | E5: 30 | F5: 14.7 | G5: Light | H5: 8000
A6: Welded Mesh | B6: 2 | C6: 50 | D6: 0.0025 | E6: 30 | F6: 70 | G6: Heavy | H6: 6000
A7: Totals | H7: =SUM(H2:H6) -> 26000
A9: Weight of steel wire coil | B9: 2500
A10: Length of raw material coil (m) | B10: 7000 | C10: Original diameter (m) | D10: 0.005
B12: Length of coil on exit (m) | C12: Weight per meter (kg) | D12: Metres per roll | E12: Rolls per annum | F12: m needed per annum | G12: km needed per annum
A13: Bird Netting | B13: =((($D$10/2)^2)*$B$10)/((D2/2)^2) -> 486111.11 | C13: =$B$9/B13 -> 0.0051428571 | D13: =F2/C13 -> 4375 | E13: =H2*1000/F2 -> 177777.78 | F13: =D13*E13 -> 7.7777778e+08 | G13: =F13/1000 -> 777777.78
A14: Chicken Netting | B14: =((($D$10/2)^2)*$B$10)/((D3/2)^2) -> 216049.38 | C14: =$B$9/B14 -> 0.011571429 | D14: =F3/C14 -> 3620.9877 | E14: =H3*1000/F3 -> 131264.92 | F14: =D14*E14 -> 4.7530864e+08 | G14: =F14/1000 -> 475308.64
A15: Jackal Netting | B15: =((($D$10/2)^2)*$B$10)/((D4/2)^2) -> 54012.346 | C15: =$B$9/B15 -> 0.046285714 | D15: =F4/C15 -> 421.2963 | E15: =H4*1000/F4 -> 128205.13 | F15: =D15*E15 -> 54012346 | G15: =F15/1000 -> 54012.346
A16: Pig Netting | B16: =((($D$10/2)^2)*$B$10)/((D5/2)^2) -> 54012.346 | C16: =$B$9/B16 -> 0.046285714 | D16: =F5/C16 -> 317.59259 | E16: =H5*1000/F5 -> 544217.69 | F16: =D16*E16 -> 1.7283951e+08 | G16: =F16/1000 -> 172839.51
A17: Welded Mesh | B17: =((($D$10/2)^2)*$B$10)/((D6/2)^2) -> 28000 | C17: =$B$9/B17 -> 0.089285714 | D17: =F6/C17 -> 784 | E17: =H6*1000/F6 -> 85714.286 | F17: =D17*E17 -> 67200000 | G17: =F17/1000 -> 67200
A18: Total | B18: =SUM(B13:B17) -> 838185.19 | C18: =SUM(C13:C17) -> 0.19857143 | D18: =SUM(D13:D17) -> 9518.8765 | E18: =SUM(E13:E17) -> 1067179.8 | F18: =SUM(F13:F17) -> 1.5471383e+09 | G18: =SUM(G13:G17) -> 1547138.3
A20: Days worked per day | B20: 220
B21: After draw | D21: Before draw | F21: With 4% scrap allowance (after draw) | H21: With 4% scrap allowance (before draw)
B22: m per day | C22: km per day | D22: m per day | E22: km per day | F22: m per day | G22: km per day | H22: m per day | I22: km per day
A23: Bird Netting | B23: =F13/$B$20 -> 3535353.5 | C23: =B23/1000 -> 3535.3535 | D23: =(((D2/2)^2)*B23)/(($D$10/2)^2) -> 50909.091 | E23: =D23/1000 -> 50.909091 | F23: =B23/0.96 -> 3682659.9 | G23: =F23/1000 -> 3682.6599 | H23: =D23/0.96 -> 53030.303 | I23: =H23/1000 -> 53.030303
A24: Chicken Netting | B24: =F14/$B$20 -> 2160493.8 | C24: =B24/1000 -> 2160.4938 | D24: =(((D3/2)^2)*B24)/(($D$10/2)^2) -> 70000 | E24: =D24/1000 -> 70 | F24: =B24/0.96 -> 2250514.4 | G24: =F24/1000 -> 2250.5144 | H24: =D24/0.96 -> 72916.667 | I24: =H24/1000 -> 72.916667
A25: Jackal Netting | B25: =F15/$B$20 -> 245510.66 | C25: =B25/1000 -> 245.51066 | D25: =(((D4/2)^2)*B25)/(($D$10/2)^2) -> 31818.182 | E25: =D25/1000 -> 31.818182 | F25: =B25/0.96 -> 255740.27 | G25: =F25/1000 -> 255.74027 | H25: =D25/0.96 -> 33143.939 | I25: =H25/1000 -> 33.143939
A26: Pig Netting | B26: =F16/$B$20 -> 785634.12 | C26: =B26/1000 -> 785.63412 | D26: =(((D5/2)^2)*B26)/(($D$10/2)^2) -> 101818.18 | E26: =D26/1000 -> 101.81818 | F26: =B26/0.96 -> 818368.87 | G26: =F26/1000 -> 818.36887 | H26: =D26/0.96 -> 106060.61 | I26: =H26/1000 -> 106.06061
A27: Welded Mesh | B27: =F17/$B$20 -> 305454.55 | C27: =B27/1000 -> 305.45455 | D27: =(((D6/2)^2)*B27)/(($D$10/2)^2) -> 76363.636 | E27: =D27/1000 -> 76.363636 | F27: =B27/0.96 -> 318181.82 | G27: =F27/1000 -> 318.18182 | H27: =D27/0.96 -> 79545.455 | I27: =H27/1000 -> 79.545455
A28: Total | B28: =SUM(B23:B27) -> 7032446.7 | C28: =SUM(C23:C27) -> 7032.4467 | D28: =SUM(D23:D27) -> 330909.09 | E28: =SUM(E23:E27) -> 330.90909 | F28: =SUM(F23:F27) -> 7325465.3 | G28: =SUM(G23:G27) -> 7325.4653 | H28: =SUM(H23:H27) -> 344696.97 | I28: =SUM(I23:I27) -> 344.69697
B30: Daily Production Requirement (m) | C30: Drawing Speed (m/s) | D30: Drawing Speed machine 2 | E30: Length one machine draws per day | F30: No. of machines needed
A31: Bird Netting | B31: =F23 -> 3682659.9 | C31: 15 | D31: 15 | E31: =C31*60*60*7 -> 378000 | F31: =ROUNDUP(B31/E31,0)*2 -> 20
A32: Chicken Netting | B32: =F24 -> 2250514.4 | C32: 15 | D32: 15 | E32: =C32*60*60*7 -> 378000 | F32: =ROUNDUP(B32/E32,0)*2 -> 12
A33: Jackal Netting | B33: =F25 -> 255740.27 | C33: 20 | D33: - | E33: =C33*60*60*7 -> 504000 | F33: =ROUNDUP(B33/E33,0) -> 1
A34: Pig Netting | B34: =F26 -> 818368.87 | C34: 20 | D34: - | E34: =C34*60*60*7 -> 504000 | F34: =ROUNDUP(B34/E34,0) -> 2
A35: Welded Mesh | B35: =F27 -> 318181.82 | C35: 20 | D35: - | E35: =C35*60*60*7 -> 504000 | F35: =ROUNDUP(B35/E35,0) -> 1
A36: Total | B36: =SUM(B31:B35) -> 7325465.3 | C36: =SUM(C31:C35) -> 90 | E36: =SUM(E31:E35) -> 2268000 | F36: =SUM(F31:F35) -> 36
E37: *use for 7hrs per day (1hr cleaning and setup time)
A39: No. of raw material coils needed | B39: =H28/7000 -> 49.242424
A40: No. of raw material coils in storage (3 days) | B40: =B39*3 -> 147.72727
B42: Height of roll (m) | C42: Roll length (m) | D42: Material thickness (m)
A43: Bird Netting | B43: 0.9 | C43: 50 | D43: =D2+0.0002 -> 0.0008
A44: Chicken Netting | B44: 1.8 | C44: 50 | D44: =D3+0.0002 -> 0.0011
A45: Jackal Netting | B45: 0.6 | C45: 50 | D45: =D4+0.0002 -> 0.002
A46: Pig Netting | B46: 0.9 | C46: 30 | D46: =D5+0.0002 -> 0.002
...

Sheet Operation B
A1: Avg galvinisation coating thickness (µm) | B1: 50 | D1: https://gaa.com.au/standard-specification-for-hot-dip-galvanizing/
A2: Avg galvinisation coating thickness (m) | B2: =B1/1000000 -> 5e-05
A3: Total metal to be galvinised per day (km) | B3: ='Operation A'!C30 -> 7032.4467
A4: Zinc density (g/cm^3) | B4: 7.14 | D4: pi | E4: =PI() -> 3.1415927
A5: Zinc mass per unit area (g/m^2) | B5: 357 | F5: *30 mins needed each morning to replenish galvanisers
F6: *work with 7hrs per day of galvanising time (1hr setup and cleaning time)
B7: Wire diameter (m) | C7: Surface area per meter (m^2) | D7: Zinc mass per meter (g) | E7: Zinc mass per km (kg) | H7: =B32 -> Daily demand (m) | I7: Zinc mass needed (kg) | J7: daily lines needed
A8: Bird Netting | B8: 0.0006 | C8: =((B8+$B$2)/2)*2*$E$4 -> 0.0020420352 | D8: =C8*$B$5*$B$4 -> 5.2051069 | E8: =(D8*1000)/1000 -> 5.2051069 | G8: Bird Netting | H8: =B33 -> 3682659.9 | I8: =H8/1000*E8 -> 19168.639 | J8: =I8/$B$20/7 -> 4.5639616
A9: Chicken Netting | B9: 0.0009 | C9: =((B9+$B$2)/2)*2*$E$4 -> 0.002984513 | D9: =C9*$B$5*$B$4 -> 7.607464 | E9: =(D9*1000)/1000 -> 7.607464 | G9: Chicken Netting | H9: =B34 -> 2250514.4 | I9: =H9/1000*E9 -> 17120.707 | J9: =I9/$B$20/7 -> 4.0763589
A10: Jackal Netting | B10: 0.0018 | C10: =((B10+$B$2)/2)*2*$E$4 -> 0.0058119464 | D10: =C10*$B$5*$B$4 -> 14.814535 | E10: =(D10*1000)/1000 -> 14.814535 | G10: Jackal Netting | H10: =B35 -> 255740.27 | I10: =H10/1000*E10 -> 3788.6733 | J10: =I10/$B$20/7 -> 0.90206506
A11: Pig Netting | B11: 0.0018 | C11: =((B11+$B$2)/2)*2*$E$4 -> 0.0058119464 | D11: =C11*$B$5*$B$4 -> 14.814535 | E11: =(D11*1000)/1000 -> 14.814535 | G11: Pig Netting | H11: =B36 -> 818368.87 | I11: =H11/1000*E11 -> 12123.754 | J11: =I11/$B$20/7 -> 2.8866082
A12: Welded Mesh | B12: 0.0025 | C12: =((B12+$B$2)/2)*2*$E$4 -> 0.0080110613 | D12: =C12*$B$5*$B$4 -> 20.420035 | E12: =(D12*1000)/1000 -> 20.420035 | G12: Welded Mesh | H12: =B37 -> 318181.82 | I12: =H12/1000*E12 -> 6497.2838 | J12: =I12/$B$20/7 -> 1.5469723
A13: Total | E13: =SUM(E8:E12) -> 62.861676 | H13: =SUM(H8:H12) -> 7325465.3 | I13: =SUM(I8:I12) -> 58699.058 | J13: =ROUNDUP(SUM(J8:J12),0) -> 14
A16: Galvaniser dimensions | B16: https://www.alibaba.com/product-detail/Customized-Galvanizing-Line-High-Speed-Capacity_1600550137652.html | H16: wire lines per machine | I16: 2
A17: Length (m) | B17: 100 | C17: =B17*B18*E28 -> 14500 | I17: machines needed
A18: Width (m) | B18: 5 | H18: Bird Netting | I18: =J8/$I$16 -> 2.2819808
A19: Depth (m) | B19: 3 | H19: Chicken Netting | I19: =J9/$I$16 -> 2.0381794
A20: Galvanising speed (kg/h) | B20: 600 | H20: Jackal Netting | I20: =J10/$I$16 -> 0.45103253
H21: Pig Netting | I21: =J11/$I$16 -> 1.4433041
B22: yearly requirement (kg) | C22: daily requirement (kg) | D22: hourly requirement (kg) | E22: machines needed | H22: Welded Mesh | I22: =J12/$I$16 -> 0.77348617
A23: Bird Netting | B23: 4000000 | C23: =B23/220 -> 18181.818 | D23: =C23/7 -> 2597.4026 | E23: =D23/$B$20 -> 4.3290043 | I23: =ROUNDUP(SUM(I18:I22),0) -> 7
A24: Chicken Netting | B24: 5500000 | C24: =B24/220 -> 25000 | D24: =C24/7 -> 3571.4286 | E24: =D24/$B$20 -> 5.952381
A25: Jackal Netting | B25: 2500000 | C25: =B25/220 -> 11363.636 | D25: =C25/7 -> 1623.3766 | E25: =D25/$B$20 -> 2.7056277
A26: Pig Netting | B26: 8000000 | C26: =B26/220 -> 36363.636 | D26: =C26/7 -> 5194.8052 | E26: =D26/$B$20 -> 8.6580087
A27: Welded Mesh | B27: 6000000 | C27: =B27/220 -> 27272.727 | D27: =C27/7 -> 3896.1039 | E27: =D27/$B$20 -> 6.4935065
B28: =SUM(B23:B27) -> 26000000 | C28: =SUM(C23:C27) -> 118181.82 | D28: =SUM(D23:D27) -> 16883.117 | E28: =ROUNDUP(SUM(E23:E27),0) -> 29
A31: Zinc ingot weight (kg) | B31: 25
B32: Daily demand (m) | C32: Wire radius (m) | D32: Surface area(M^2) | E32: gavlanised coating (kg/m^2) | F32: daily zinc demand (kg
A33: Bird Netting | B33: ='Operation A'!F25 -> 3682659.9 | C33: =B8/2 -> 0.0003 | D33: =2*$E$4*C33*B33 -> 6941.6504 | E33: 0.3 | F33: =E33*D33 -> 2082.4951
A34: Chicken Netting | B34: ='Operation A'!F26 -> 2250514.4 | C34: =B9/2 -> 0.00045 | D34: =2*$E$4*C34*B34 -> 6363.1796 | E34: 0.3 | F34: =E34*D34 -> 1908.9539
A35: Jackal Netting | B35: ='Operation A'!F27 -> 255740.27 | C35: =B10/2 -> 0.0009 | D35: =2*$E$4*C35*B35 -> 1446.1772 | E35: 0.3 | F35: =E35*D35 -> 433.85315
A36: Pig Netting | B36: ='Operation A'!F28 -> 818368.87 | C36: =B11/2 -> 0.0009 | D36: =2*$E$4*C36*B36 -> 4627.767 | E36: 0.3 | F36: =E36*D36 -> 1388.3301
A37: Welded Mesh | B37: ='Operation A'!F29 -> 318181.82 | C37: =B12/2 -> 0.00125 | D37: =2*$E$4*C37*B37 -> 2498.9942 | E37: 0.7 | F37: =E37*D37 -> 1749.2959
B38: =SUM(B33:B37) -> 7325465.3 | D38: =SUM(D33:D37) -> 21877.768 | F38: =SUM(F33:F37) -> 7562.9281
A40: No. of ingots needed daily | B40: =F38/B31 -> 302.51713
A41: No. of ingots needed for work week | B41: =B40*5 -> 1512.5856
A42: Length of pallet (m) | B42: 1
A43: Width of pallet (m) | B43: 0.5
A44: Height of pallet (m) | B44: 0.4
A45: No. of layers in pallet | B45: 10 | C45: https://www.boliden.com/48e740/globalassets/products-new/documents/zinc-shg-product-sheet-2022.pdf
...

Sheet Op.B Appendix
A1: Avg galvinisation coating thickness (µm) | B1: 50
A2: Avg galvinisation coating thickness (m) | B2: =B1/1000000 -> 5e-05
A3: Total metal to be galvinised per day (km) | B3: ='Operation A'!C30 -> 7032.4467
A4: Zinc density (g/cm^3) | B4: 7.14 | D4: pi | E4: =PI() -> 3.1415927
A5: Zinc mass per unit area (g/m^2) | B5: 357
B7: Wire diameter (m) | C7: Surface area per meter (m^2) | D7: Zinc mass per meter (g) | E7: Zinc mass per km (kg)
A8: Bird Netting | B8: 0.0006 | C8: =((B8+$B$2)/2)*2*$E$4 -> 0.0020420352 | D8: =C8*$B$5*$B$4*100 -> 520.51069 | E8: =(D8*1000)/1000 -> 520.51069
A9: Chicken Netting | B9: 0.0009 | C9: =((B9+$B$2)/2)*2*$E$4 -> 0.002984513 | D9: =C9*$B$5*$B$4*100 -> 760.7464 | E9: =(D9*1000)/1000 -> 760.7464
A10: Jackal Netting | B10: 0.0018 | C10: =((B10+$B$2)/2)*2*$E$4 -> 0.0058119464 | D10: =C10*$B$5*$B$4*100 -> 1481.4535 | E10: =(D10*1000)/1000 -> 1481.4535
A11: Pig Netting | B11: 0.0018 | C11: =((B11+$B$2)/2)*2*$E$4 -> 0.0058119464 | D11: =C11*$B$5*$B$4*100 -> 1481.4535 | E11: =(D11*1000)/1000 -> 1481.4535
A12: Welded Mesh | B12: 0.0025 | C12: =((B12+$B$2)/2)*2*$E$4 -> 0.0080110613 | D12: =C12*$B$5*$B$4*100 -> 2042.0035 | E12: =(D12*1000)/1000 -> 2042.0035
A13: Total | E13: =SUM(E8:E12) -> 6286.1676
A15: Galvaniser dimensions:
A16: Length (m) | B16: 100
A17: Width (m) | B17: 5
A18: Depth (m) | B18: 3
A19: Galvanising speed (kg/h) | B19: 600
B21: yearly requirement (kg) | C21: daily requirement (kg) | D21: hourly requirement (kg) | E21: machines needed | F21: *work with 7hrs per day of galvanising time (1hr setup and cleaning time)
A22: Bird Netting | B22: 4000000 | C22: =B22/220 -> 18181.818 | D22: =C22/7 -> 2597.4026 | E22: =D22/$B$19/4 -> 1.0822511
A23: Chicken Netting | B23: 5500000 | C23: =B23/220 -> 25000 | D23: =C23/7 -> 3571.4286 | E23: =D23/$B$19/4 -> 1.4880952
A24: Jackal Netting | B24: 2500000 | C24: =B24/220 -> 11363.636 | D24: =C24/7 -> 1623.3766 | E24: =D24/$B$19/4 -> 0.67640693
A25: Pig Netting | B25: 8000000 | C25: =B25/220 -> 36363.636 | D25: =C25/7 -> 5194.8052 | E25: =D25/$B$19/4 -> 2.1645022
A26: Welded Mesh | B26: 6000000 | C26: =B26/220 -> 27272.727 | D26: =C26/7 -> 3896.1039 | E26: =D26/$B$19/4 -> 1.6233766
B27: =SUM(B22:B26) -> 26000000 | C27: =SUM(C22:C26) -> 118181.82 | D27: =SUM(D22:D26) -> 16883.117 | E27: 7
A29: Zinc ingot weight (kg) | B29: 25
B30: Daily demand (m) | C30: Wire radius (m) | D30: Surface area(M^2) | E30: gavlanised coating (kg/m^2) | F30: daily zinc demand (kg
A31: Bird Netting | B31: 3682659.9 | C31: 0.0003 | D31: 6941.6504 | E31: 0.3 | F31: 2082.4951
A32: Chicken Netting | B32: 2250514.4 | C32: 0.00045 | D32: 6363.1796 | E32: 0.3 | F32: 1908.9539
A33: Jackal Netting | B33: 255740.27 | C33: 0.0009 | D33: 1446.1772 | E33: 0.3 | F33: 433.85315
A34: Pig Netting | B34: 818368.87 | C34: 0.0009 | D34: 4627.767 | E34: 0.3 | F34: 1388.3301
A35: Welded Mesh | B35: 318181.82 | C35: 0.00125 | D35: 2498.9942 | E35: 0.7 | F35: 1749.2959
B36: 7325465.3 | D36: 21877.768 | F36: 7562.9281
A38: No. of ingots needed daily | B38: =F36/B29 -> 302.51713
A39: No. of ingots needed for work week | B39: =B38*5 -> 1512.5856
A40: Length of pallet (m) | B40: 1
A41: Width of pallet (m) | B41: 0.5
A42: Height of pallet (m) | B42: 0.4
A43: No. of layers in pallet | B43: 10
A44: No. of slabs on a pallet layer | B44: 8
A45: Area for 5 days storage (sqm) | B45: =B39/(B44*B43)*(B41*B40) -> 9.4536602
